Workbook

Sheet EGRESOS 2025
A1: Fecha Pago | B1: Mes Devengo | C1: Descripcion | D1: Proveedor | E1: Monto Total | F1: Tipo Doc | G1: Forma Pago | H1: Nombre Cuenta | I1: IVA | J1: Monto Neto | K1: Cuenta | L1: CC
A2: 45323 | B2: 2024-02 | C2: Pago Recurrente VD Google LLC GSUI | E2: 57291 | F2: F | G2: Debito | H2: Plataformas Digitales | I2: 9147 | J2: 48144 | K2: 1.5.1 | L2: CC5
A3: 45324 | B3: 2024-02 | C3: PAGO EN LINEA CHILEXPRESS | E3: 61391 | F3: F | G3: Debito | H3: Despachos B2B (Gaspar) | I3: 9802 | J3: 51589 | K3: 1.7.1 | L3: CC7
A4: 45327 | B4: 2024-02 | C4: Compra Nacional HIP LIDER BUENAVEN | E4: 9480 | F4: F | G4: Credito | H4: Ingredientes | I4: 1514 | J4: 7966 | K4: 1.1.1 | L4: CC1
A5: 45327 | B5: 2024-02 | C5: Compra RAPPI PRIME RAPPI | E5: 4990 | F5: F | G5: Credito | H5: Comision Plataformas Delivery | I5: 797 | J5: 4193 | K5: 1.8.2 | L5: CC8
A6: 45328 | B6: 2024-02 | C6: Compra Nacional CLUB REPOSTERO SPA | E6: 2590 | F6: F | G6: Credito | H6: Ingredientes | I6: 414 | J6: 2176 | K6: 1.1.1 | L6: CC1
A7: 45328 | B7: 2024-02 | C7: Compra Nacional HIP LIDER BUENAVEN | E7: 210 | F7: F | G7: Credito | H7: Ingredientes | I7: 34 | J7: 176 | K7: 1.1.1 | L7: CC1
A8: 45328 | B8: 2024-02 | C8: Compra Nacional NP FLOW | E8: 99979 | F8: F | G8: Credito | H8: Equipamiento Local | I8: 15963 | J8: 84016 | K8: 1.3.10 | L8: CC3
A9: 45328 | B9: 2024-02 | C9: Compra Nacional LAPIZ LOPEZ | E9: 5960 | F9: F | G9: Credito | H9: Equipamiento Local | I9: 952 | J9: 5008 | K9: 1.3.10 | L9: CC3
A10: 45328 | B10: 2024-02 | C10: Compra Internacional FACEBK *5PT5J | E10: 31600 | F10: F | G10: Credito | H10: RRSS | I10: 5045 | J10: 26555 | K10: 1.6.1 | L10: CC6
A11: 45330 | B11: 2024-02 | C11: Compra Nacional NP ALVI TOBALABA O | E11: 55104 | F11: F | G11: Credito | H11: Ingredientes | I11: 8798 | J11: 46306 | K11: 1.1.1 | L11: CC1
A12: 45330 | B12: 2024-02 | C12: Compra Nacional NP ALVI TOBALABA O | E12: 36736 | F12: F | G12: Credito | H12: Ingredientes | I12: 5865 | J12: 30871 | K12: 1.1.1 | L12: CC1
A13: 45330 | B13: 2024-02 | C13: Compra Nacional MERPAGO*PAPADINSPA | E13: 20400 | F13: F | G13: Credito | H13: Ingredientes | I13: 3257 | J13: 17143 | K13: 1.1.1 | L13: CC1
... A817: 46112 | B817: 2026-03 | C817: Compra FACEBK *NAJMMJ9VJ | E817: 343624 | F817: F | G817: Credito | H817: RRSS | I817: 54864 | J817: 288760 | K817: 1.6.1 | L817: CC6
A818: 45323 | B818: 2024-02 | C818: Transf.Internet a 81.094.100-6 | D818: COOPERATIVA AGRICOLA Y LECHERA DE LA UNION LTDA. | E818: 321409 | F818: F | G818: Debito | H818: Ingredientes | I818: 51317 | J818: 270092 | K818: 1.1.1 | L818: CC1
A819: 45323 | B819: 2024-01 | C819: Transf.Internet a 19.567.111-7 | D819: Maria Jose Grez (sueldo) | E819: 2790 | F819: S | G819: Debito | H819: Sueldos con Contrato | I819: 0 | J819: 2790 | K819: 1.2.1 | L819: CC2
A820: 45323 | B820: 2024-01 | C820: Transf.Internet a 18.732.574-9 | D820: Sueldo | E820: 100000 | F820: S | G820: Debito | H820: Sueldos con Contrato | I820: 0 | J820: 100000 | K820: 1.2.1 | L820: CC2
A821: 45323 | B821: 2024-01 | C821: Transf.Internet a 21.093.602-5 | D821: Nataly Morales (sueldo) | E821: 325000 | F821: S | G821: Debito | H821: Sueldos con Contrato | I821: 0 | J821: 325000 | K821: 1.2.1 | L821: CC2
A822: 45323 | B822: 2024-02 | C822: Transf.Internet a 19.324.205-7 | D822: Catalina Cuevas (honorarios marketing) | E822: 400000 | F822: S | G822: Debito | H822: Honorarios | I822: 0 | J822: 400000 | K822: 1.2.2 | L822: CC2
A823: 45323 | B823: 2024-01 | C823: Transf.Internet a 19.567.111-7 | D823: Maria Jose Grez (sueldo) | E823: 400000 | F823: S | G823: Debito | H823: Sueldos con Contrato | I823: 0 | J823: 400000 | K823: 1.2.1 | L823: CC2
A824: 45323 | B824: 2024-01 | C824: Transf.Internet a 19.606.694-2 | D824: Josefina Landaeta (sueldo) | E824: 400000 | F824: S | G824: Debito | H824: Sueldos con Contrato | I824: 0 | J824: 400000 | K824: 1.2.1 | L824: CC2
A825: 45323 | B825: 2024-01 | C825: Transf.Internet a 19.606.694-2 | D825: Josefina Landaeta (sueldo) | E825: 400000 | F825: S | G825: Debito | H825: Sueldos con Contrato | I825: 0 | J825: 400000 | K825: 1.2.1 | L825: CC2
A826: 45323 | B826: 2024-01 | C826: Transf.Internet a 19.567.111-7 | D826: Maria Jose Grez (sueldo) | E826: 400000 | F826: S | G826: Debito | H826: Sueldos con Contrato | I826: 0 | J826: 400000 | K826: 1.2.1 | L826: CC2
A827: 45323 | B827: 2024-01 | C827: Transf.Internet a 17.083.572-7 | D827: Ignacia Grez (retiro duena) | E827: 400000 | F827: S | G827: Debito | H827: Sueldos con Contrato | I827: 0 | J827: 400000 | K827: 1.2.1 | L827: CC2
A828: 45323 | B828: 2024-02 | C828: Transf.Internet a 6.551.524-5 | D828: Despachos Horeca (6.551.524-5) | E828: 7880 | F828: S | G828: Debito | H828: Despachos B2B (Gaspar) | I828: 0 | J828: 7880 | K828: 1.7.1 | L828: CC7
A829: 45324 | B829: 2024-02 | C829: Transf.Internet a 78.383.730-7 | D829: AVICOLA Y COMERCIAL EL TOCO LTDA | E829: 59400 | F829: F | G829: Debito | H829: Ingredientes | I829: 9484 | J829: 49916 | K829: 1.1.1 | L829: CC1
... A847: 45338 | B847: 2024-02 | C847: Transf.Internet a 76.669.508-6 | D847: ENVIAME LATAM SPA | E847: 362422 | F847: F | G847: Debito | H847: Despachos B2B (Gaspar) | I847: 57866 | J847: 304556 | K847: 1.7.1 | L847: CC7
A848: 45344 | B848: 2024-02 | C848: Compra Nacional RAN SPA | E848: 1400 | F848: S | G848: Credito | I848: 0 | J848: 1400 | K848: 1.3.6 | L848: CC3
A849: 45344 | B849: 2024-02 | C849: Compra Nacional SUCURSAL APUMANQUE | E849: 16250 | F849: S | G849: Credito | I849: 0 | J849: 16250 | K849: 1.3.6 | L849: CC3
A850: 45345 | B850: 2024-01 | C850: Transf.Internet a 19.076.816-3 | D850: Sueldo | E850: 250000 | F850: S | G850: Debito | H850: Sueldos con Contrato | I850: 0 | J850: 250000 | K850: 1.2.1 | L850: CC2
A851: 45348 | B851: 2024-01 | C851: Transf.Internet a 21.572.942-7 | D851: Sueldo | E851: 200000 | F851: S | G851: Debito | H851: Sueldos con Contrato | I851: 0 | J851: 200000 | K851: 1.2.1 | L851: CC2
A852: 45349 | B852: 2024-02 | C852: Transf.Internet a 19.324.205-7 | D852: Catalina Cuevas (honorarios marketing) | E852: 11200 | F852: S | G852: Debito | H852: Honorarios | I852: 0 | J852: 11200 | K852: 1.2.2 | L852: CC2
A853: 45351 | B853: 2024-02 | C853: Transf.Internet a 81.094.100-6 | D853: COOPERATIVA AGRICOLA Y LECHERA DE LA UNION LTDA. | E853: 42969 | F853: F | G853: Debito | H853: Ingredientes | I853: 6861 | J853: 36108 | K853: 1.1.1 | L853: CC1
A854: 45351 | B854: 2024-02 | C854: Transf.Internet a 76.934.534-5 | D854: AT CONTADORES SERVICIOS PROFESIONALES LIMITADA | E854: 45000 | F854: F | G854: Debito | H854: Asesoria Contable | I854: 7185 | J854: 37815 | K854: 1.2.3 | L854: CC2
A855: 45351 | B855: 2024-01 | C855: Transf.Internet a 21.093.602-5 | D855: Nataly Morales (sueldo) | E855: 325000 | F855: S | G855: Debito | H855: Sueldos con Contrato | I855: 0 | J855: 325000 | K855: 1.2.1 | L855: CC2
A856: 45351 | B856: 2024-02 | C856: Transf.Internet a 19.324.205-7 | D856: Catalina Cuevas (honorarios marketing) | E856: 400000 | F856: S | G856: Debito | H856: Honorarios | I856: 0 | J856: 400000 | K856: 1.2.2 | L856: CC2
A857: 45351 | B857: 2024-01 | C857: Transf.Internet a 17.083.572-7 | D857: Ignacia Grez (retiro duena) | E857: 400000 | F857: S | G857: Debito | H857: Sueldos con Contrato | I857: 0 | J857: 400000 | K857: 1.2.1 | L857: CC2
A858: 45351 | B858: 2024-01 | C858: Transf.Internet a 19.606.694-2 | D858: Josefina Landaeta (sueldo) | E858: 800000 | F858: S | G858: Debito | H858: Sueldos con Contrato | I858: 0 | J858: 800000 | K858: 1.2.1 | L858: CC2
A859: 45351 | B859: 2024-01 | C859: Transf.Internet a 19.567.111-7 | D859: Maria Jose Grez (sueldo) | E859: 800000 | F859: S | G859: Debito | H859: Sueldos con Contrato | I859: 0 | J859: 800000 | K859: 1.2.1 | L859: CC2
A860: 45351 | B860: 2024-02 | C860: Transf.Internet a 76.860.819-9 | D860: AGENCIA DE PUBLICIDAD RORAIMA DIGITAL LIMITADA | E860: 17850 | F860: F | G860: Debito | H860: RRSS | I860: 2850 | J860: 15000 | K860: 1.6.1 | L860: CC6
...

Sheet Resumen
A1: Mes Devengo | B1: CC1 Costos Producto | C1: CC2 Sueldos | D1: CC3 Infraestructura | E1: CC4 Carrito | F1: CC5 Plataformas Digitales | G1: CC6 Marketing | H1: CC7 Logistica | I1: CC8 Comisiones | J1: CC9 Impuestos | K1: TOTAL
A2: 2025-01 | B2: 3542555 | C2: 1601559 | D2: 1770166 | F2: 1270508 | G2: 509471 | H2: 87948 | I2: 4193 | J2: 33442 | K2: =+SUM(B2:J2) -> 8819842
A3: 2025-02 | C3: 8151421 | J3: 1055433 | K3: =+SUM(B3:J3) -> 9206854
A4: 2025-03 | B4: 2102400 | C4: 5416208 | D4: 1046705 | E4: 390000 | F4: 930769 | G4: 609405 | H4: 95154 | I4: 54420 | J4: 1684643 | K4: =+SUM(B4:J4) -> 12329704
A5: 2025-04 | B5: 5468426 | C5: 5180655 | D5: 2267053 | E5: 520000 | F5: 1289353 | G5: 241080 | H5: 91292 | I5: 19531 | J5: 2028841 | K5: =+SUM(B5:J5) -> 17106231
A6: 2025-05 | B6: 5975278 | C6: 5397366 | D6: 2207267 | E6: 1714271 | F6: 1123685 | G6: 1055463 | H6: 111775 | I6: 30158 | J6: 1781383 | K6: =+SUM(B6:J6) -> 19396646
A7: 2025-06 | B7: 6802920 | C7: 9673034 | D7: 2662253 | E7: 588922 | F7: 1513352 | G7: 741769 | H7: 140638 | I7: 22967 | J7: 1585026 | K7: =+SUM(B7:J7) -> 23730881
A8: 2025-07 | B8: 4501491 | C8: 3772466 | D8: 2780933 | E8: 25000 | F8: 1619437 | G8: 1143524 | H8: 155377 | I8: 44407 | J8: 1895184 | K8: =+SUM(B8:J8) -> 15937819
A9: 2025-08 | B9: 4124880 | C9: 6412311 | D9: 2621844 | E9: 645002 | F9: 1357282 | G9: 931670 | H9: 127385 | I9: 5979 | J9: 2347740 | K9: =+SUM(B9:J9) -> 18574093
A10: 2025-09 | B10: 4137176 | C10: 11662962 | D10: 2640613 | E10: 1006036 | F10: 1235007 | G10: 623561 | H10: 178648 | I10: 26828 | J10: 1936260 | K10: =+SUM(B10:J10) -> 23447091
A11: 2025-10 | B11: 4387607 | C11: 3998259 | D11: 57867500 | F11: 1649247 | G11: 758966 | H11: 98038 | I11: 31928 | J11: 1395392 | K11: =+SUM(B11:J11) -> 70186937
A12: 2025-11 | B12: 4365818 | C12: 6611057 | D12: 7065137 | E12: 545002 | F12: 1561367 | G12: 448323 | H12: 113459 | I12: 54812 | J12: 2034764 | K12: =+SUM(B12:J12) -> 22799739
A13: 2025-12 | B13: 5443210 | C13: 7162631 | D13: 6270337 | E13: 514794 | F13: 1168034 | G13: 2269081 | H13: 570128 | I13: 2492 | J13: 2278363 | K13: =+SUM(B13:J13) -> 25679070
A14: 2026-01 | B14: 5578871 | C14: 9849594 | D14: 5849410 | E14: 551261 | F14: 1833190 | G14: 827746 | H14: 559074 | J14: 2425979 | K14: =+SUM(B14:J14) -> 27475125
A15: 2026-02 | B15: 1287402 | C15: 8745073 | D15: 3652697 | E15: 605767 | F15: 871065 | G15: 719473 | H15: 467200 | J15: 2147617 | K15: =+SUM(B15:J15) -> 18496294
A16: 2026-03 | B16: 7592596 | C16: 853701 | D16: 3683962 | F16: 977940 | G16: 2081341 | H16: 593130 | J16: 1926212 | K16: =+SUM(B16:J16) -> 17708882
A17: TOTAL ANUAL | B17: =+SUM(B2:B16) -> 65310630 | C17: =+SUM(C2:C16) -> 94488297 | D17: =+SUM(D2:D16) -> 102385877 | E17: =+SUM(E2:E16) -> 7106055 | F17: =+SUM(F2:F16) -> 18400236 | G17: =+SUM(G2:G16) -> 12960873 | H17: =+SUM(H2:H16) -> 3389246 | I17: =+SUM(I2:I16) -> 297715 | J17: =+SUM(J2:J16) -> 26556279 | K17: =+SUM(B17:J17) -> 330895208

Sheet Pendientes
A1: Fecha Pago | B1: Mes Devengo | C1: Descripcion | D1: Monto Total | E1: Nombre DTE | F1: Nombre Cuenta | G1: Codigo | H1: CC
A2: 45323 | B2: 2024-02 | C2: Transf.Internet a 18.732.574-9 | D2: 100000 | G2: =+_xlfn.XLOOKUP(F2,Listas!$B:$B,Listas!$A:$A,0,0) -> 0 | H2: =+_xlfn.XLOOKUP(F2,Listas!$B:$B,Listas!$C:$C,0,0) -> 0
A3: 45323 | B3: 2024-02 | C3: Transf.Internet a 6.551.524-5 | D3: 7880 | G3: =+_xlfn.XLOOKUP(F3,Listas!$B:$B,Listas!$A:$A,0,0) -> 0 | H3: =+_xlfn.XLOOKUP(F3,Listas!$B:$B,Listas!$C:$C,0,0) -> 0
A4: 45324 | B4: 2024-02 | C4: Transf.Internet a 26.715.306-K | D4: 400000 | G4: =+_xlfn.XLOOKUP(F4,Listas!$B:$B,Listas!$A:$A,0,0) -> 0 | H4: =+_xlfn.XLOOKUP(F4,Listas!$B:$B,Listas!$C:$C,0,0) -> 0
A5: 45328 | B5: 2024-02 | C5: Transf.Internet a 14.680.015-7 | D5: 53550 | G5: =+_xlfn.XLOOKUP(F5,Listas!$B:$B,Listas!$A:$A,0,0) -> 0 | H5: =+_xlfn.XLOOKUP(F5,Listas!$B:$B,Listas!$C:$C,0,0) -> 0
A6: 45328 | B6: 2024-02 | C6: Compra Nacional LAPIZ LOPEZ | D6: 5960 | G6: =+_xlfn.XLOOKUP(F6,Listas!$B:$B,Listas!$A:$A,0,0) -> 0 | H6: =+_xlfn.XLOOKUP(F6,Listas!$B:$B,Listas!$C:$C,0,0) -> 0
A7: 45328 | B7: 2024-02 | C7: Compra Nacional NP FLOW | D7: 99979 | G7: =+_xlfn.XLOOKUP(F7,Listas!$B:$B,Listas!$A:$A,0,0) -> 0 | H7: =+_xlfn.XLOOKUP(F7,Listas!$B:$B,Listas!$C:$C,0,0) -> 0
A8: 45330 | B8: 2024-02 | C8: Compra Nacional NP ALVI TOBALABA O | D8: 36736 | G8: =+_xlfn.XLOOKUP(F8,Listas!$B:$B,Listas!$A:$A,0,0) -> 0 | H8: =+_xlfn.XLOOKUP(F8,Listas!$B:$B,Listas!$C:$C,0,0) -> 0
A9: 45330 | B9: 2024-02 | C9: Compra Nacional NP ALVI TOBALABA O | D9: 55104 | G9: =+_xlfn.XLOOKUP(F9,Listas!$B:$B,Listas!$A:$A,0,0) -> 0 | H9: =+_xlfn.XLOOKUP(F9,Listas!$B:$B,Listas!$C:$C,0,0) -> 0
A10: 45344 | B10: 2024-02 | C10: Compra Nacional RAN SPA | D10: 1400 | G10: =+_xlfn.XLOOKUP(F10,Listas!$B:$B,Listas!$A:$A,0,0) -> 0 | H10: =+_xlfn.XLOOKUP(F10,Listas!$B:$B,Listas!$C:$C,0,0) -> 0
A11: 45344 | B11: 2024-02 | C11: Compra Nacional SUCURSAL APUMANQUE | D11: 16250 | G11: =+_xlfn.XLOOKUP(F11,Listas!$B:$B,Listas!$A:$A,0,0) -> 0 | H11: =+_xlfn.XLOOKUP(F11,Listas!$B:$B,Listas!$C:$C,0,0) -> 0
A12: 45345 | B12: 2024-02 | C12: Transf.Internet a 19.076.816-3 | D12: 250000 | G12: =+_xlfn.XLOOKUP(F12,Listas!$B:$B,Listas!$A:$A,0,0) -> 0 | H12: =+_xlfn.XLOOKUP(F12,Listas!$B:$B,Listas!$C:$C,0,0) -> 0
A13: 45348 | B13: 2024-02 | C13: Transf.Internet a 21.572.942-7 | D13: 200000 | G13: =+_xlfn.XLOOKUP(F13,Listas!$B:$B,Listas!$A:$A,0,0) -> 0 | H13: =+_xlfn.XLOOKUP(F13,Listas!$B:$B,Listas!$C:$C,0,0) -> 0
... A22: 45659 | B22: 2025-01 | C22: Compra Inter. NP www.aliexpress.co | D22: 3776 | G22: =+_xlfn.XLOOKUP(F22,Listas!$B:$B,Listas!$A:$A,0,0) -> 0 | H22: =+_xlfn.XLOOKUP(F22,Listas!$B:$B,Listas!$C:$C,0,0) -> 0
A23: 45659 | B23: 2025-01 | C23: Transf.Internet a 77.931.120-1 | D23: 41995 | E23: DTE: Homs | G23: =+_xlfn.XLOOKUP(F23,Listas!$B:$B,Listas!$A:$A,0,0) -> 0 | H23: =+_xlfn.XLOOKUP(F23,Listas!$B:$B,Listas!$C:$C,0,0) -> 0
A24: 45663 | B24: 2025-01 | C24: Transf.Internet a 26.715.306-K | D24: 145000 | G24: =+_xlfn.XLOOKUP(F24,Listas!$B:$B,Listas!$A:$A,0,0) -> 0 | H24: =+_xlfn.XLOOKUP(F24,Listas!$B:$B,Listas!$C:$C,0,0) -> 0
A25: 45663 | B25: 2025-01 | C25: Compra Nacional MERPAGO*3PRODUCTOS | D25: 28380 | G25: =+_xlfn.XLOOKUP(F25,Listas!$B:$B,Listas!$A:$A,0,0) -> 0 | H25: =+_xlfn.XLOOKUP(F25,Listas!$B:$B,Listas!$C:$C,0,0) -> 0
A26: 45663 | B26: 2025-01 | C26: Transf.Internet a 26.715.306-K | D26: 540000 | G26: =+_xlfn.XLOOKUP(F26,Listas!$B:$B,Listas!$A:$A,0,0) -> 0 | H26: =+_xlfn.XLOOKUP(F26,Listas!$B:$B,Listas!$C:$C,0,0) -> 0
A27: 45666 | B27: 2025-01 | C27: Pago Recurrente VD APP-SORTEOS.COM | D27: 9221 | G27: =+_xlfn.XLOOKUP(F27,Listas!$B:$B,Listas!$A:$A,0,0) -> 0 | H27: =+_xlfn.XLOOKUP(F27,Listas!$B:$B,Listas!$C:$C,0,0) -> 0
A28: 45671 | B28: 2025-01 | C28: Compra Nacional NP FLOW | D28: 107656 | G28: =+_xlfn.XLOOKUP(F28,Listas!$B:$B,Listas!$A:$A,0,0) -> 0 | H28: =+_xlfn.XLOOKUP(F28,Listas!$B:$B,Listas!$C:$C,0,0) -> 0
A29: 45671 | B29: 2025-01 | C29: Transf.Internet a 6.551.524-5 | D29: 10940 | G29: =+_xlfn.XLOOKUP(F29,Listas!$B:$B,Listas!$A:$A,0,0) -> 0 | H29: =+_xlfn.XLOOKUP(F29,Listas!$B:$B,Listas!$C:$C,0,0) -> 0
A30: 45671 | B30: 2025-01 | C30: Compra Nacional MERPAGO*9PRODUCTOS | D30: 45654 | G30: =+_xlfn.XLOOKUP(F30,Listas!$B:$B,Listas!$A:$A,0,0) -> 0 | H30: =+_xlfn.XLOOKUP(F30,Listas!$B:$B,Listas!$C:$C,0,0) -> 0
A31: 45679 | B31: 2025-01 | C31: Compra Nacional THE CAKE CLUB | D31: 105160 | G31: =+_xlfn.XLOOKUP(F31,Listas!$B:$B,Listas!$A:$A,0,0) -> 0 | H31: =+_xlfn.XLOOKUP(F31,Listas!$B:$B,Listas!$C:$C,0,0) -> 0
A32: 45679 | B32: 2025-01 | C32: Transf.Internet a 6.551.524-5 | D32: 19606 | G32: =+_xlfn.XLOOKUP(F32,Listas!$B:$B,Listas!$A:$A,0,0) -> 0 | H32: =+_xlfn.XLOOKUP(F32,Listas!$B:$B,Listas!$C:$C,0,0) -> 0
A33: 45684 | B33: 2025-01 | C33: Transf.Internet a 6.551.524-5 | D33: 23154 | G33: =+_xlfn.XLOOKUP(F33,Listas!$B:$B,Listas!$A:$A,0,0) -> 0 | H33: =+_xlfn.XLOOKUP(F33,Listas!$B:$B,Listas!$C:$C,0,0) -> 0
A34: 45685 | B34: 2025-01 | C34: Compra Nacional NP FLOW | D34: 24900 | G34: =+_xlfn.XLOOKUP(F34,Listas!$B:$B,Listas!$A:$A,0,0) -> 0 | H34: =+_xlfn.XLOOKUP(F34,Listas!$B:$B,Listas!$C:$C,0,0) -> 0
A35: 45685 | B35: 2025-01 | C35: Compra Nacional MERPAGO*10PRODUCTO | D35: 58850 | G35: =+_xlfn.XLOOKUP(F35,Listas!$B:$B,Listas!$A:$A,0,0) -> 0 | H35: =+_xlfn.XLOOKUP(F35,Listas!$B:$B,Listas!$C:$C,0,0) -> 0
... A123: 45855 | B123: 2025-07 | C123: Transf.Internet a 22.809.808-6 | D123: 150000 | G123: =+_xlfn.XLOOKUP(F123,Listas!$B:$B,Listas!$A:$A,0,0) -> 0 | H123: =+_xlfn.XLOOKUP(F123,Listas!$B:$B,Listas!$C:$C,0,0) -> 0
A124: 45855 | B124: 2025-07 | C124: Transf.Internet a 77.931.120-1 | D124: 36146 | E124: DTE: Homs | G124: =+_xlfn.XLOOKUP(F124,Listas!$B:$B,Listas!$A:$A,0,0) -> 0 | H124: =+_xlfn.XLOOKUP(F124,Listas!$B:$B,Listas!$C:$C,0,0) -> 0
A125: 45856 | B125: 2025-07 | C125: Compra DP *FALABELLA | D125: 19970 | G125: =+_xlfn.XLOOKUP(F125,Listas!$B:$B,Listas!$A:$A,0,0) -> 0 | H125: =+_xlfn.XLOOKUP(F125,Listas!$B:$B,Listas!$C:$C,0,0) -> 0
A126: 45859 | B126: 2025-07 | C126: Compra SUCURSAL APUMANQU | D126: 7990 | G126: =+_xlfn.XLOOKUP(F126,Listas!$B:$B,Listas!$A:$A,0,0) -> 0 | H126: =+_xlfn.XLOOKUP(F126,Listas!$B:$B,Listas!$C:$C,0,0) -> 0
A127: 45861 | B127: 2025-07 | C127: Compra MERCADOPAGO *BYWA | D127: 2500 | G127: =+_xlfn.XLOOKUP(F127,Listas!$B:$B,Listas!$A:$A,0,0) -> 0 | H127: =+_xlfn.XLOOKUP(F127,Listas!$B:$B,Listas!$C:$C,0,0) -> 0
A128: 45863 | B128: 2025-07 | C128: Compra DP *FALABELLA | D128: 32740 | G128: =+_xlfn.XLOOKUP(F128,Listas!$B:$B,Listas!$A:$A,0,0) -> 0 | H128: =+_xlfn.XLOOKUP(F128,Listas!$B:$B,Listas!$C:$C,0,0) -> 0
A129: 45863 | B129: 2025-07 | C129: Compra DP *FALABELLA | D129: 32740 | G129: =+_xlfn.XLOOKUP(F129,Listas!$B:$B,Listas!$A:$A,0,0) -> 0 | H129: =+_xlfn.XLOOKUP(F129,Listas!$B:$B,Listas!$C:$C,0,0) -> 0
A130: 45863 | B130: 2025-07 | C130: 0065515245 Transf a Luis Felipe Gr | D130: 63000 | G130: =+_xlfn.XLOOKUP(F130,Listas!$B:$B,Listas!$A:$A,0,0) -> 0 | H130: =+_xlfn.XLOOKUP(F130,Listas!$B:$B,Listas!$C:$C,0,0) -> 0
A131: 45866 | B131: 2025-07 | C131: Compra SALA VENTAS VITAC | D131: 2680 | G131: =+_xlfn.XLOOKUP(F131,Listas!$B:$B,Listas!$A:$A,0,0) -> 0 | H131: =+_xlfn.XLOOKUP(F131,Listas!$B:$B,Listas!$C:$C,0,0) -> 0
A132: 45869 | B132: 2025-07 | C132: Transf.Internet a 20.830.554-9 | D132: 100000 | G132: =+_xlfn.XLOOKUP(F132,Listas!$B:$B,Listas!$A:$A,0,0) -> 0 | H132: =+_xlfn.XLOOKUP(F132,Listas!$B:$B,Listas!$C:$C,0,0) -> 0
A133: 45869 | B133: 2025-07 | C133: 0965569405 Transf a Proveedores in | D133: 143844 | G133: =+_xlfn.XLOOKUP(F133,Listas!$B:$B,Listas!$A:$A,0,0) -> 0 | H133: =+_xlfn.XLOOKUP(F133,Listas!$B:$B,Listas!$C:$C,0,0) -> 0
A134: 45869 | B134: 2025-07 | C134: Transf.Internet a 22.809.808-6 | D134: 363000 | G134: =+_xlfn.XLOOKUP(F134,Listas!$B:$B,Listas!$A:$A,0,0) -> 0 | H134: =+_xlfn.XLOOKUP(F134,Listas!$B:$B,Listas!$C:$C,0,0) -> 0
A135: 45869 | B135: 2025-07 | C135: 0765020417 Transf a MUNDO ETIQUETA | D135: 55942 | G135: =+_xlfn.XLOOKUP(F135,Listas!$B:$B,Listas!$A:$A,0,0) -> 0 | H135: =+_xlfn.XLOOKUP(F135,Listas!$B:$B,Listas!$C:$C,0,0) -> 0
...

Sheet Listas
A1: Codigo | B1: Nombre | C1: CC
A2: 1.1.1 | B2: Ingredientes | C2: CC1
A3: 1.1.2 | B3: Packaging | C3: CC1
A4: 1.1.3 | B4: Equipamiento de Cocina | C4: CC1
A5: 1.2.1 | B5: Sueldos con Contrato | C5: CC2
A6: 1.2.2 | B6: Honorarios | C6: CC2
A7: 1.2.3 | B7: Asesoria Contable | C7: CC2
A8: 1.2.4 | B8: Uniformes Personal | C8: CC2
A9: 1.2.5 | B9: Prestamos Personal | C9: CC2
A10: 1.3.1 | B10: Arriendo Local | C10: CC3
A11: 1.3.2 | B11: Agua | C11: CC3
A12: 1.3.3 | B12: Luz | C12: CC3
... A40: 1.9.5 | B40: Gastos Bancarios | C40: CC9
A42: 1.8.3 | B42: Plataformas Digitales (Comision)
A43: CC9 | B43: Impuestos
A44: 1.9.1 | B44: IVA Neto (F29)
A45: 1.9.2 | B45: Provision Impuesto a la Renta
A46: 1.9.3 | B46: Impuesto a la Renta
A47: 1.9.4 | B47: Patente Comercial
A48: 1.9.5 | B48: Gastos Bancarios
