Workbook

Sheet 1. INGRESOS
A1: Fecha | B1: Mes Devengo | C1: Cliente | D1: Descripcion | E1: Monto Total | F1: Tipo Doc | G1: IVA | H1: Monto Neto | I1: Cuenta | J1: Nombre Cuenta | K1: Canal
A2: 45658 | B2: 2025-01 | C2: Rebeca Uribe Fridman | D2: CANELÉ TRADICIONAL | E2: 23790 | F2: B | G2: 3798 | H2: 19992 | I2: 3.2 | J2: Ventas Personas (B2C) | K2: CH2
A3: 45659 | B3: 2025-01 | C3: GALVEZ Y HEUSSER SPA | D3: HORECA CATERING | E3: 71035 | F3: F | G3: 11342 | H3: 59693 | I3: 3.1 | J3: Ventas HoReCa | K3: CH1
A4: 45659 | B4: 2025-01 | C4: HUERTO SUR LIMITADA | D4: HORECA CAFETERIA | E4: 89589 | F4: F | G4: 14304 | H4: 75285 | I4: 3.1 | J4: Ventas HoReCa | K4: CH1
A5: 45659 | B5: 2025-01 | C5: Sin cliente | D5: CANELÉ TRADICIONAL | E5: 11120 | F5: B | G5: 1775 | H5: 9345 | I5: 3.2 | J5: Ventas Personas (B2C) | K5: CH2
A6: 45659 | B6: 2025-01 | C6: CAFÉ UNDER SPA | D6: HORECA CAFETERIA | E6: 63990 | F6: F | G6: 10217 | H6: 53773 | I6: 3.1 | J6: Ventas HoReCa | K6: CH1
A7: 45659 | B7: 2025-01 | C7: Carolina Rivera | D7: PACKS GOURMET | E7: 24786 | F7: B | G7: 3957 | H7: 20829 | I7: 3.2 | J7: Ventas Personas (B2C) | K7: CH2
A8: 45659 | B8: 2025-01 | C8: Santa María spa | D8: HORECA CAFETERIA | E8: 178711 | F8: F | G8: 28534 | H8: 150177 | I8: 3.1 | J8: Ventas HoReCa | K8: CH1
A9: 45659 | B9: 2025-01 | C9: Nicole Stefanic | D9: CANELE SIN AZUCAR | E9: 28289 | F9: B | G9: 4517 | H9: 23772 | I9: 3.2 | J9: Ventas Personas (B2C) | K9: CH2
A10: 45659 | B10: 2025-01 | C10: Candelaria Mackay | D10: PACKS GOURMET | E10: 21705 | F10: B | G10: 3466 | H10: 18239 | I10: 3.2 | J10: Ventas Personas (B2C) | K10: CH2
A11: 45659 | B11: 2025-01 | C11: Sin cliente | D11: CANELÉ TRADICIONAL | E11: 13900 | F11: B | G11: 2219 | H11: 11681 | I11: 3.2 | J11: Ventas Personas (B2C) | K11: CH2
A12: 45660 | B12: 2025-01 | C12: Belén Pérez Silva | D12: CANELÉ TRADICIONAL | E12: 17890 | F12: B | G12: 2856 | H12: 15034 | I12: 3.2 | J12: Ventas Personas (B2C) | K12: CH2
A13: 45660 | B13: 2025-01 | C13: Antonio Maino | D13: CANELÉ TRADICIONAL | E13: 17890 | F13: B | G13: 2856 | H13: 15034 | I13: 3.2 | J13: Ventas Personas (B2C) | K13: CH2
... A7248: 46157 | B7248: 2026-05 | C7248: BLUE OAK COFFE SPA | D7248: HORECA CAFETERIA | E7248: 77564 | F7248: F | G7248: 12384 | H7248: 65180 | I7248: 3.1 | J7248: Ventas HoReCa | K7248: CH1

Sheet 2. EGRESOS
A1: Fecha Pago | B1: Mes Devengo | C1: Descripcion | D1: Proveedor | E1: Monto Total | F1: Tipo Doc | G1: Forma Pago | H1: Nombre Cuenta | I1: IVA | J1: Monto Neto | K1: Cuenta | L1: CC
A2: 46113 | B2: 2026-03 | C2: Sueldo 22.520.465-9 - Carolina Gutierrez | E2: 1127159 | G2: Debito | H2: Sueldos con Contrato | I2: =IF(F2="F",ROUND(E2*0.19/1.19,0),0) | J2: =IF(E2="","",E2-I2) | K2: =+_xlfn.XLOOKUP(Tabla1[[#This Row],[Nombre Cuenta]],PLAN_CUENTAS!$B$2:$B$100,PLAN_CUENTAS!$A$2:$A$100,0,0) | L2: =+_xlfn.XLOOKUP(Tabla1[[#This Row],[Nombre Cuenta]],PLAN_CUENTAS!$B$2:$B$100,PLAN_CUENTAS!$C$2:$C$100,0,0)
A3: 46113 | B3: 2026-03 | C3: Sueldo 22.520.465-9 - Carolina Gutierrez | E3: 825400 | G3: Debito | H3: Sueldos con Contrato | I3: =IF(F3="F",ROUND(E3*0.19/1.19,0),0) | J3: =IF(E3="","",E3-I3) | K3: =+_xlfn.XLOOKUP(Tabla1[[#This Row],[Nombre Cuenta]],PLAN_CUENTAS!$B$2:$B$100,PLAN_CUENTAS!$A$2:$A$100,0,0) | L3: =+_xlfn.XLOOKUP(Tabla1[[#This Row],[Nombre Cuenta]],PLAN_CUENTAS!$B$2:$B$100,PLAN_CUENTAS!$C$2:$C$100,0,0)
A4: 46113 | B4: 2026-03 | C4: Sueldo 17.083.572-7 - M Ignacia Grez | E4: 800000 | G4: Debito | H4: Sueldos con Contrato | I4: =IF(F4="F",ROUND(E4*0.19/1.19,0),0) | J4: =IF(E4="","",E4-I4) | K4: =+_xlfn.XLOOKUP(Tabla1[[#This Row],[Nombre Cuenta]],PLAN_CUENTAS!$B$2:$B$100,PLAN_CUENTAS!$A$2:$A$100,0,0) | L4: =+_xlfn.XLOOKUP(Tabla1[[#This Row],[Nombre Cuenta]],PLAN_CUENTAS!$B$2:$B$100,PLAN_CUENTAS!$C$2:$C$100,0,0)
A5: 46113 | B5: 2026-03 | C5: Sueldo 19.324.205-7 - Catalina Cuevas | E5: 700000 | G5: Debito | H5: Honorarios | I5: =IF(F5="F",ROUND(E5*0.19/1.19,0),0) | J5: =IF(E5="","",E5-I5) | K5: =+_xlfn.XLOOKUP(Tabla1[[#This Row],[Nombre Cuenta]],PLAN_CUENTAS!$B$2:$B$100,PLAN_CUENTAS!$A$2:$A$100,0,0) | L5: =+_xlfn.XLOOKUP(Tabla1[[#This Row],[Nombre Cuenta]],PLAN_CUENTAS!$B$2:$B$100,PLAN_CUENTAS!$C$2:$C$100,0,0)
A6: 46113 | B6: 2026-03 | C6: Sueldo 21.093.602-5 - Nataly Morales | E6: 682252 | G6: Debito | H6: Sueldos con Contrato | I6: =IF(F6="F",ROUND(E6*0.19/1.19,0),0) | J6: =IF(E6="","",E6-I6) | K6: =+_xlfn.XLOOKUP(Tabla1[[#This Row],[Nombre Cuenta]],PLAN_CUENTAS!$B$2:$B$100,PLAN_CUENTAS!$A$2:$A$100,0,0) | L6: =+_xlfn.XLOOKUP(Tabla1[[#This Row],[Nombre Cuenta]],PLAN_CUENTAS!$B$2:$B$100,PLAN_CUENTAS!$C$2:$C$100,0,0)
A7: 46113 | B7: 2026-03 | C7: Sueldo 18.866.000-2 - Camila Aguilera | E7: 627742 | G7: Debito | H7: Sueldos con Contrato | I7: =IF(F7="F",ROUND(E7*0.19/1.19,0),0) | J7: =IF(E7="","",E7-I7) | K7: =+_xlfn.XLOOKUP(Tabla1[[#This Row],[Nombre Cuenta]],PLAN_CUENTAS!$B$2:$B$100,PLAN_CUENTAS!$A$2:$A$100,0,0) | L7: =+_xlfn.XLOOKUP(Tabla1[[#This Row],[Nombre Cuenta]],PLAN_CUENTAS!$B$2:$B$100,PLAN_CUENTAS!$C$2:$C$100,0,0)
A8: 46113 | B8: 2026-03 | C8: Sueldo 10.325.328-4 - Patricia Guijuelos | E8: 551261 | G8: Debito | H8: Sueldos con Contrato | I8: =IF(F8="F",ROUND(E8*0.19/1.19,0),0) | J8: =IF(E8="","",E8-I8) | K8: =+_xlfn.XLOOKUP(Tabla1[[#This Row],[Nombre Cuenta]],PLAN_CUENTAS!$B$2:$B$100,PLAN_CUENTAS!$A$2:$A$100,0,0) | L8: =+_xlfn.XLOOKUP(Tabla1[[#This Row],[Nombre Cuenta]],PLAN_CUENTAS!$B$2:$B$100,PLAN_CUENTAS!$C$2:$C$100,0,0)
A9: 46113 | B9: 2026-03 | C9: Sueldo 20.550.382-k - Veronica Alvarez | E9: 456803 | G9: Debito | H9: Honorarios | I9: =IF(F9="F",ROUND(E9*0.19/1.19,0),0) | J9: =IF(E9="","",E9-I9) | K9: =+_xlfn.XLOOKUP(Tabla1[[#This Row],[Nombre Cuenta]],PLAN_CUENTAS!$B$2:$B$100,PLAN_CUENTAS!$A$2:$A$100,0,0) | L9: =+_xlfn.XLOOKUP(Tabla1[[#This Row],[Nombre Cuenta]],PLAN_CUENTAS!$B$2:$B$100,PLAN_CUENTAS!$C$2:$C$100,0,0)
A10: 46113 | B10: 2026-03 | C10: Sueldo 18.831.462-7 - Katherine Chamorro | E10: 236667 | G10: Debito | H10: Honorarios | I10: =IF(F10="F",ROUND(E10*0.19/1.19,0),0) | J10: =IF(E10="","",E10-I10) | K10: =+_xlfn.XLOOKUP(Tabla1[[#This Row],[Nombre Cuenta]],PLAN_CUENTAS!$B$2:$B$100,PLAN_CUENTAS!$A$2:$A$100,0,0) | L10: =+_xlfn.XLOOKUP(Tabla1[[#This Row],[Nombre Cuenta]],PLAN_CUENTAS!$B$2:$B$100,PLAN_CUENTAS!$C$2:$C$100,0,0)
A11: 46113 | B11: 2026-03 | C11: Sueldo 21.920.200-8 - Catalina Arriagada | E11: 213750 | G11: Debito | H11: Honorarios | I11: =IF(F11="F",ROUND(E11*0.19/1.19,0),0) | J11: =IF(E11="","",E11-I11) | K11: =+_xlfn.XLOOKUP(Tabla1[[#This Row],[Nombre Cuenta]],PLAN_CUENTAS!$B$2:$B$100,PLAN_CUENTAS!$A$2:$A$100,0,0) | L11: =+_xlfn.XLOOKUP(Tabla1[[#This Row],[Nombre Cuenta]],PLAN_CUENTAS!$B$2:$B$100,PLAN_CUENTAS!$C$2:$C$100,0,0)
A12: 46113 | B12: 2026-03 | C12: Sueldo 21.832.228-K - Emilia Bravo | E12: 177975 | G12: Debito | H12: Honorarios | I12: =IF(F12="F",ROUND(E12*0.19/1.19,0),0) | J12: =IF(E12="","",E12-I12) | K12: =+_xlfn.XLOOKUP(Tabla1[[#This Row],[Nombre Cuenta]],PLAN_CUENTAS!$B$2:$B$100,PLAN_CUENTAS!$A$2:$A$100,0,0) | L12: =+_xlfn.XLOOKUP(Tabla1[[#This Row],[Nombre Cuenta]],PLAN_CUENTAS!$B$2:$B$100,PLAN_CUENTAS!$C$2:$C$100,0,0)
A13: 46113 | B13: 2026-03 | C13: Sueldo 21.380.644-0 - Elizabeth Caceres | E13: 146718 | G13: Debito | H13: Honorarios | I13: =IF(F13="F",ROUND(E13*0.19/1.19,0),0) | J13: =IF(E13="","",E13-I13) | K13: =+_xlfn.XLOOKUP(Tabla1[[#This Row],[Nombre Cuenta]],PLAN_CUENTAS!$B$2:$B$100,PLAN_CUENTAS!$A$2:$A$100,0,0) | L13: =+_xlfn.XLOOKUP(Tabla1[[#This Row],[Nombre Cuenta]],PLAN_CUENTAS!$B$2:$B$100,PLAN_CUENTAS!$C$2:$C$100,0,0)
A14: 46113 | B14: 2026-04 | C14: Mensualidad Plataforma Bsale | D14: Bsale Chile S.A | E14: 137494 | F14: F | G14: Debito | H14: Plataformas Digitales | I14: =IF(F14="F",ROUND(E14*0.19/1.19,0),0) | J14: =IF(E14="","",E14-I14) | K14: =+_xlfn.XLOOKUP(Tabla1[[#This Row],[Nombre Cuenta]],PLAN_CUENTAS!$B$2:$B$100,PLAN_CUENTAS!$A$2:$A$100,0,0) | L14: =+_xlfn.XLOOKUP(Tabla1[[#This Row],[Nombre Cuenta]],PLAN_CUENTAS!$B$2:$B$100,PLAN_CUENTAS!$C$2:$C$100,0,0)
A15: 46113 | B15: 2026-04 | C15: Google Workspace (7 correos) | D15: Google Workspace | E15: 111702 | F15: F | G15: Debito | H15: Plataformas Digitales | I15: =IF(F15="F",ROUND(E15*0.19/1.19,0),0) | J15: =IF(E15="","",E15-I15) | K15: =+_xlfn.XLOOKUP(Tabla1[[#This Row],[Nombre Cuenta]],PLAN_CUENTAS!$B$2:$B$100,PLAN_CUENTAS!$A$2:$A$100,0,0) | L15: =+_xlfn.XLOOKUP(Tabla1[[#This Row],[Nombre Cuenta]],PLAN_CUENTAS!$B$2:$B$100,PLAN_CUENTAS!$C$2:$C$100,0,0)
A16: 46113 | B16: 2026-03 | C16: Sueldo - 21.575.375-1 - Martina Jorquera | E16: 100000 | G16: Debito | H16: Honorarios | I16: =IF(F16="F",ROUND(E16*0.19/1.19,0),0) | J16: =IF(E16="","",E16-I16) | K16: =+_xlfn.XLOOKUP(Tabla1[[#This Row],[Nombre Cuenta]],PLAN_CUENTAS!$B$2:$B$100,PLAN_CUENTAS!$A$2:$A$100,0,0) | L16: =+_xlfn.XLOOKUP(Tabla1[[#This Row],[Nombre Cuenta]],PLAN_CUENTAS!$B$2:$B$100,PLAN_CUENTAS!$C$2:$C$100,0,0)
A17: 46113 | B17: 2026-04 | C17: Transf.Internet a 76.803.503-2 | D17: Sticker Shop | E17: 99853 | F17: S | G17: Debito | H17: Packaging | I17: =IF(F17="F",ROUND(E17*0.19/1.19,0),0) | J17: =IF(E17="","",E17-I17) | K17: =+_xlfn.XLOOKUP(Tabla1[[#This Row],[Nombre Cuenta]],PLAN_CUENTAS!$B$2:$B$100,PLAN_CUENTAS!$A$2:$A$100,0,0) | L17: =+_xlfn.XLOOKUP(Tabla1[[#This Row],[Nombre Cuenta]],PLAN_CUENTAS!$B$2:$B$100,PLAN_CUENTAS!$C$2:$C$100,0,0)
A18: 46113 | B18: 2026-04 | C18: Transf.Internet a 77.190.532-3 | D18: Sticker Print | E18: 64260 | F18: F | G18: Debito | H18: Packaging | I18: =IF(F18="F",ROUND(E18*0.19/1.19,0),0) | J18: =IF(E18="","",E18-I18) | K18: =+_xlfn.XLOOKUP(Tabla1[[#This Row],[Nombre Cuenta]],PLAN_CUENTAS!$B$2:$B$100,PLAN_CUENTAS!$A$2:$A$100,0,0) | L18: =+_xlfn.XLOOKUP(Tabla1[[#This Row],[Nombre Cuenta]],PLAN_CUENTAS!$B$2:$B$100,PLAN_CUENTAS!$C$2:$C$100,0,0)
A19: 46113 | B19: 2026-04 | C19: Compra TOKU *VERISURE | D19: Verisure | E19: 59265 | F19: F | G19: Debito | H19: Seguridad | I19: =IF(F19="F",ROUND(E19*0.19/1.19,0),0) | J19: =IF(E19="","",E19-I19) | K19: =+_xlfn.XLOOKUP(Tabla1[[#This Row],[Nombre Cuenta]],PLAN_CUENTAS!$B$2:$B$100,PLAN_CUENTAS!$A$2:$A$100,0,0) | L19: =+_xlfn.XLOOKUP(Tabla1[[#This Row],[Nombre Cuenta]],PLAN_CUENTAS!$B$2:$B$100,PLAN_CUENTAS!$C$2:$C$100,0,0)
A20: 46113 | B20: 2026-04 | C20: Estampado Camisa Despachador B2B | D20: VINCULO EXPERIENCE SPA | E20: 7599 | F20: F | G20: Debito | H20: Uniformes Personal | I20: =IF(F20="F",ROUND(E20*0.19/1.19,0),0) | J20: =IF(E20="","",E20-I20) | K20: =+_xlfn.XLOOKUP(Tabla1[[#This Row],[Nombre Cuenta]],PLAN_CUENTAS!$B$2:$B$100,PLAN_CUENTAS!$A$2:$A$100,0,0) | L20: =+_xlfn.XLOOKUP(Tabla1[[#This Row],[Nombre Cuenta]],PLAN_CUENTAS!$B$2:$B$100,PLAN_CUENTAS!$C$2:$C$100,0,0)
A21: 46113 | B21: 2026-04 | C21: Transf.Internet a 77.512.163-7 | D21: Ecourier | E21: 3332 | F21: F | G21: Debito | H21: Despachos B2C | I21: =IF(F21="F",ROUND(E21*0.19/1.19,0),0) | J21: =IF(E21="","",E21-I21) | K21: =+_xlfn.XLOOKUP(Tabla1[[#This Row],[Nombre Cuenta]],PLAN_CUENTAS!$B$2:$B$100,PLAN_CUENTAS!$A$2:$A$100,0,0) | L21: =+_xlfn.XLOOKUP(Tabla1[[#This Row],[Nombre Cuenta]],PLAN_CUENTAS!$B$2:$B$100,PLAN_CUENTAS!$C$2:$C$100,0,0)
A22: 46113 | B22: 2026-04 | C22: Compra MP *CABIFY2614VSC | D22: Cabify | E22: 2679 | F22: F | G22: Debito | H22: Transporte Personas (Empleados) | I22: =IF(F22="F",ROUND(E22*0.19/1.19,0),0) | J22: =IF(E22="","",E22-I22) | K22: =+_xlfn.XLOOKUP(Tabla1[[#This Row],[Nombre Cuenta]],PLAN_CUENTAS!$B$2:$B$100,PLAN_CUENTAS!$A$2:$A$100,0,0) | L22: =+_xlfn.XLOOKUP(Tabla1[[#This Row],[Nombre Cuenta]],PLAN_CUENTAS!$B$2:$B$100,PLAN_CUENTAS!$C$2:$C$100,0,0)
A23: 46113 | B23: 2026-04 | C23: Compra MP *CABIFY2614NSZ | D23: Cabify | E23: 2660 | F23: F | G23: Debito | H23: Transporte Personas (Empleados) | I23: =IF(F23="F",ROUND(E23*0.19/1.19,0),0) | J23: =IF(E23="","",E23-I23) | K23: =+_xlfn.XLOOKUP(Tabla1[[#This Row],[Nombre Cuenta]],PLAN_CUENTAS!$B$2:$B$100,PLAN_CUENTAS!$A$2:$A$100,0,0) | L23: =+_xlfn.XLOOKUP(Tabla1[[#This Row],[Nombre Cuenta]],PLAN_CUENTAS!$B$2:$B$100,PLAN_CUENTAS!$C$2:$C$100,0,0)
A24: 46114 | B24: 2026-04 | C24: Transf.Internet a 15.411.174-3 | D24: TECNOLOGIA VERDE SPA | E24: 70000 | F24: F | G24: Debito | H24: Despachos B2B (Gaspar) | I24: =IF(F24="F",ROUND(E24*0.19/1.19,0),0) | J24: =IF(E24="","",E24-I24) | K24: =+_xlfn.XLOOKUP(Tabla1[[#This Row],[Nombre Cuenta]],PLAN_CUENTAS!$B$2:$B$100,PLAN_CUENTAS!$A$2:$A$100,0,0) | L24: =+_xlfn.XLOOKUP(Tabla1[[#This Row],[Nombre Cuenta]],PLAN_CUENTAS!$B$2:$B$100,PLAN_CUENTAS!$C$2:$C$100,0,0)
A25: 46114 | B25: 2026-05 | C25: 76.839.579-9 - Tarjetas PPT 50% del total | D25: SERVICIOS DIGITALES E IMPRESIÓN OSEG SPA | E25: 60150 | F25: F | G25: Debito | H25: Packaging | I25: =IF(F25="F",ROUND(E25*0.19/1.19,0),0) | J25: =IF(E25="","",E25-I25) | K25: =+_xlfn.XLOOKUP(Tabla1[[#This Row],[Nombre Cuenta]],PLAN_CUENTAS!$B$2:$B$100,PLAN_CUENTAS!$A$2:$A$100,0,0) | L25: =+_xlfn.XLOOKUP(Tabla1[[#This Row],[Nombre Cuenta]],PLAN_CUENTAS!$B$2:$B$100,PLAN_CUENTAS!$C$2:$C$100,0,0)
A26: 46114 | B26: 2026-04 | C26: Vajilla faltante terraza | D26: LIDER | E26: 37790 | F26: F | G26: Debito | H26: Equipamiento Local | I26: =IF(F26="F",ROUND(E26*0.19/1.19,0),0) | J26: =IF(E26="","",E26-I26) | K26: =+_xlfn.XLOOKUP(Tabla1[[#This Row],[Nombre Cuenta]],PLAN_CUENTAS!$B$2:$B$100,PLAN_CUENTAS!$A$2:$A$100,0,0) | L26: =+_xlfn.XLOOKUP(Tabla1[[#This Row],[Nombre Cuenta]],PLAN_CUENTAS!$B$2:$B$100,PLAN_CUENTAS!$C$2:$C$100,0,0)
A27: 46114 | B27: 2026-04 | C27: Compra OPENAI *CHATGPT S | D27: CHATGPT | E27: 18825 | G27: Debito | H27: Plataformas Digitales | I27: =IF(F27="F",ROUND(E27*0.19/1.19,0),0) | J27: =IF(E27="","",E27-I27) | K27: =+_xlfn.XLOOKUP(Tabla1[[#This Row],[Nombre Cuenta]],PLAN_CUENTAS!$B$2:$B$100,PLAN_CUENTAS!$A$2:$A$100,0,0) | L27: =+_xlfn.XLOOKUP(Tabla1[[#This Row],[Nombre Cuenta]],PLAN_CUENTAS!$B$2:$B$100,PLAN_CUENTAS!$C$2:$C$100,0,0)
A28: 46114 | B28: 2026-04 | C28: Compra MP *CABIFY2614X8T | D28: Cabify | E28: 2846 | F28: F | G28: Debito | H28: Transporte Personas (Empleados) | I28: =IF(F28="F",ROUND(E28*0.19/1.19,0),0) | J28: =IF(E28="","",E28-I28) | K28: =+_xlfn.XLOOKUP(Tabla1[[#This Row],[Nombre Cuenta]],PLAN_CUENTAS!$B$2:$B$100,PLAN_CUENTAS!$A$2:$A$100,0,0) | L28: =+_xlfn.XLOOKUP(Tabla1[[#This Row],[Nombre Cuenta]],PLAN_CUENTAS!$B$2:$B$100,PLAN_CUENTAS!$C$2:$C$100,0,0)
A29: 46114 | B29: 2026-04 | C29: Compra MP *CABIFY2614OE3 | D29: Cabify | E29: 2846 | F29: F | G29: Debito | H29: Transporte Personas (Empleados) | I29: =IF(F29="F",ROUND(E29*0.19/1.19,0),0) | J29: =IF(E29="","",E29-I29) | K29: =+_xlfn.XLOOKUP(Tabla1[[#This Row],[Nombre Cuenta]],PLAN_CUENTAS!$B$2:$B$100,PLAN_CUENTAS!$A$2:$A$100,0,0) | L29: =+_xlfn.XLOOKUP(Tabla1[[#This Row],[Nombre Cuenta]],PLAN_CUENTAS!$B$2:$B$100,PLAN_CUENTAS!$C$2:$C$100,0,0)
A30: 46118 | B30: 2026-04 | C30: 17.403.946-1 - Arriendo Local | D30: Florencia Castro | E30: 3386546 | G30: Debito | H30: Arriendo Local | I30: =IF(F30="F",ROUND(E30*0.19/1.19,0),0) | J30: =IF(E30="","",E30-I30) | K30: =+_xlfn.XLOOKUP(Tabla1[[#This Row],[Nombre Cuenta]],PLAN_CUENTAS!$B$2:$B$100,PLAN_CUENTAS!$A$2:$A$100,0,0) | L30: =+_xlfn.XLOOKUP(Tabla1[[#This Row],[Nombre Cuenta]],PLAN_CUENTAS!$B$2:$B$100,PLAN_CUENTAS!$C$2:$C$100,0,0)
A31: 46118 | B31: 2026-04 | C31: 18.831.462-7 - Katherine Chamorro - Moto | E31: 1200000 | G31: Debito | H31: Prestamos Personal | I31: =IF(F31="F",ROUND(E31*0.19/1.19,0),0) | J31: =IF(E31="","",E31-I31) | K31: =+_xlfn.XLOOKUP(Tabla1[[#This Row],[Nombre Cuenta]],PLAN_CUENTAS!$B$2:$B$100,PLAN_CUENTAS!$A$2:$A$100,0,0) | L31: =+_xlfn.XLOOKUP(Tabla1[[#This Row],[Nombre Cuenta]],PLAN_CUENTAS!$B$2:$B$100,PLAN_CUENTAS!$C$2:$C$100,0,0)
A32: 46118 | B32: 2026-03 | C32: 77.305.867-9 - Gaspar | D32: SERVICIOS INTEGRALES DAGA SPA | E32: 707967 | F32: F | G32: Debito | H32: Despachos B2B (Gaspar) | I32: =IF(F32="F",ROUND(E32*0.19/1.19,0),0) | J32: =IF(E32="","",E32-I32) | K32: =+_xlfn.XLOOKUP(Tabla1[[#This Row],[Nombre Cuenta]],PLAN_CUENTAS!$B$2:$B$100,PLAN_CUENTAS!$A$2:$A$100,0,0) | L32: =+_xlfn.XLOOKUP(Tabla1[[#This Row],[Nombre Cuenta]],PLAN_CUENTAS!$B$2:$B$100,PLAN_CUENTAS!$C$2:$C$100,0,0)
A33: 46118 | B33: 2026-03 | C33: 76.041.249-K - Martin Iturrieta | D33: MARKETING ADVERTISING AND SALES | E33: 702100 | F33: F | G33: Debito | H33: Produccion Audiovisual | I33: =IF(F33="F",ROUND(E33*0.19/1.19,0),0) | J33: =IF(E33="","",E33-I33) | K33: =+_xlfn.XLOOKUP(Tabla1[[#This Row],[Nombre Cuenta]],PLAN_CUENTAS!$B$2:$B$100,PLAN_CUENTAS!$A$2:$A$100,0,0) | L33: =+_xlfn.XLOOKUP(Tabla1[[#This Row],[Nombre Cuenta]],PLAN_CUENTAS!$B$2:$B$100,PLAN_CUENTAS!$C$2:$C$100,0,0)
A34: 46118 | B34: 2026-04 | C34: Transf.Internet a 77.298.762-5 | D34: TECNOLOGIA VERDE SPA | E34: 107100 | F34: F | G34: Debito | H34: Despachos B2B (Gaspar) | I34: =IF(F34="F",ROUND(E34*0.19/1.19,0),0) | J34: =IF(E34="","",E34-I34) | K34: =+_xlfn.XLOOKUP(Tabla1[[#This Row],[Nombre Cuenta]],PLAN_CUENTAS!$B$2:$B$100,PLAN_CUENTAS!$A$2:$A$100,0,0) | L34: =+_xlfn.XLOOKUP(Tabla1[[#This Row],[Nombre Cuenta]],PLAN_CUENTAS!$B$2:$B$100,PLAN_CUENTAS!$C$2:$C$100,0,0)
A35: 46118 | B35: 2026-03 | C35: 77.305.867-9 - Gaspar (Iva chofer niños ignacia) | D35: SERVICIOS INTEGRALES DAGA SPA | E35: 95200 | F35: F | G35: Debito | H35: Despachos B2B (Gaspar) | I35: =IF(F35="F",ROUND(E35*0.19/1.19,0),0) | J35: =IF(E35="","",E35-I35) | K35: =+_xlfn.XLOOKUP(Tabla1[[#This Row],[Nombre Cuenta]],PLAN_CUENTAS!$B$2:$B$100,PLAN_CUENTAS!$A$2:$A$100,0,0) | L35: =+_xlfn.XLOOKUP(Tabla1[[#This Row],[Nombre Cuenta]],PLAN_CUENTAS!$B$2:$B$100,PLAN_CUENTAS!$C$2:$C$100,0,0)
A36: 46118 | B36: 2026-04 | C36: Compra MP *EKIPOTELCL | D36: Ekipotel | E36: 43503 | F36: F | G36: Debito | H36: Ferias y Eventos | I36: =IF(F36="F",ROUND(E36*0.19/1.19,0),0) | J36: =IF(E36="","",E36-I36) | K36: =+_xlfn.XLOOKUP(Tabla1[[#This Row],[Nombre Cuenta]],PLAN_CUENTAS!$B$2:$B$100,PLAN_CUENTAS!$A$2:$A$100,0,0) | L36: =+_xlfn.XLOOKUP(Tabla1[[#This Row],[Nombre Cuenta]],PLAN_CUENTAS!$B$2:$B$100,PLAN_CUENTAS!$C$2:$C$100,0,0)
A37: 46118 | B37: 2026-04 | C37: Compra PADDLE.NET* APPCH | D37: CHATGPT | E37: 18861 | G37: Debito | H37: Plataformas Digitales | I37: =IF(F37="F",ROUND(E37*0.19/1.19,0),0) | J37: =IF(E37="","",E37-I37) | K37: =+_xlfn.XLOOKUP(Tabla1[[#This Row],[Nombre Cuenta]],PLAN_CUENTAS!$B$2:$B$100,PLAN_CUENTAS!$A$2:$A$100,0,0) | L37: =+_xlfn.XLOOKUP(Tabla1[[#This Row],[Nombre Cuenta]],PLAN_CUENTAS!$B$2:$B$100,PLAN_CUENTAS!$C$2:$C$100,0,0)
A38: 46118 | B38: 2026-04 | C38: Compra CABIFY | D38: Cabify | E38: 4107 | F38: F | G38: Debito | H38: Transporte Personas (Empleados) | I38: =IF(F38="F",ROUND(E38*0.19/1.19,0),0) | J38: =IF(E38="","",E38-I38) | K38: =+_xlfn.XLOOKUP(Tabla1[[#This Row],[Nombre Cuenta]],PLAN_CUENTAS!$B$2:$B$100,PLAN_CUENTAS!$A$2:$A$100,0,0) | L38: =+_xlfn.XLOOKUP(Tabla1[[#This Row],[Nombre Cuenta]],PLAN_CUENTAS!$B$2:$B$100,PLAN_CUENTAS!$C$2:$C$100,0,0)
A39: 46119 | B39: 2026-04 | C39: Pago Cuota Crédito N° 420051171054 | D39: Banco Santander | E39: 1926881 | G39: Debito | H39: Gastos Bancarios | I39: =IF(F39="F",ROUND(E39*0.19/1.19,0),0) | J39: =IF(E39="","",E39-I39) | K39: =+_xlfn.XLOOKUP(Tabla1[[#This Row],[Nombre Cuenta]],PLAN_CUENTAS!$B$2:$B$100,PLAN_CUENTAS!$A$2:$A$100,0,0) | L39: =+_xlfn.XLOOKUP(Tabla1[[#This Row],[Nombre Cuenta]],PLAN_CUENTAS!$B$2:$B$100,PLAN_CUENTAS!$C$2:$C$100,0,0)
A40: 46119 | B40: 2026-04 | C40: Amortización Periódica LCA N° 0020 | D40: Banco Santander | E40: 631740 | G40: Debito | H40: Gastos Bancarios | I40: =IF(F40="F",ROUND(E40*0.19/1.19,0),0) | J40: =IF(E40="","",E40-I40) | K40: =+_xlfn.XLOOKUP(Tabla1[[#This Row],[Nombre Cuenta]],PLAN_CUENTAS!$B$2:$B$100,PLAN_CUENTAS!$A$2:$A$100,0,0) | L40: =+_xlfn.XLOOKUP(Tabla1[[#This Row],[Nombre Cuenta]],PLAN_CUENTAS!$B$2:$B$100,PLAN_CUENTAS!$C$2:$C$100,0,0)
...

Sheet 3. Flujo de Caja
C1: RESUMEN MENSUAL — FAIT PAR MARIE | Plan de Cuentas 2025-2026
C2: Basado en Mes Devengo (no fecha de pago). Ingresos y costos en Monto Neto sin IVA.
A3: N | B3: CC / Cuenta | C3: 2025-01 | D3: 2025-02 | E3: 2025-03 | F3: 2025-04 | G3: 2025-05 | H3: 2025-06 | I3: 2025-07 | J3: 2025-08 | K3: 2025-09 | L3: 2025-10 | M3: 2025-11 | N3: 2025-12 | O3: 2026-01 | P3: 2026-02 | Q3: 2026-03 | R3: 2026-04 | S3: 2026-05 | T3: 2026-06 | U3: 2026-07 | V3: 2026-08 | W3: 2026-09 | X3: 2026-10 | Y3: 2026-11 | Z3: 2026-12
A4: INGRESOS
A5: 2.1 | B5: Ventas HoReCa | C5: =SUMIFS('1. INGRESOS'!$E:$E,'1. INGRESOS'!$I:$I,$A5,'1. INGRESOS'!$B:$B,C$3) | D5: =SUMIFS('1. INGRESOS'!$E:$E,'1. INGRESOS'!$I:$I,$A5,'1. INGRESOS'!$B:$B,D$3) | E5: =SUMIFS('1. INGRESOS'!$E:$E,'1. INGRESOS'!$I:$I,$A5,'1. INGRESOS'!$B:$B,E$3) | F5: =SUMIFS('1. INGRESOS'!$E:$E,'1. INGRESOS'!$I:$I,$A5,'1. INGRESOS'!$B:$B,F$3) | G5: =SUMIFS('1. INGRESOS'!$E:$E,'1. INGRESOS'!$I:$I,$A5,'1. INGRESOS'!$B:$B,G$3) | H5: =SUMIFS('1. INGRESOS'!$E:$E,'1. INGRESOS'!$I:$I,$A5,'1. INGRESOS'!$B:$B,H$3) | I5: =SUMIFS('1. INGRESOS'!$E:$E,'1. INGRESOS'!$I:$I,$A5,'1. INGRESOS'!$B:$B,I$3) | J5: =SUMIFS('1. INGRESOS'!$E:$E,'1. INGRESOS'!$I:$I,$A5,'1. INGRESOS'!$B:$B,J$3) | ... Z5: =SUMIFS('1. INGRESOS'!$E:$E,'1. INGRESOS'!$I:$I,$A5,'1. INGRESOS'!$B:$B,Z$3)
A6: 2.2 | B6: Ventas Personas (B2C) | C6: =SUMIFS('1. INGRESOS'!$E:$E,'1. INGRESOS'!$I:$I,$A6,'1. INGRESOS'!$B:$B,C$3) | D6: =SUMIFS('1. INGRESOS'!$E:$E,'1. INGRESOS'!$I:$I,$A6,'1. INGRESOS'!$B:$B,D$3) | E6: =SUMIFS('1. INGRESOS'!$E:$E,'1. INGRESOS'!$I:$I,$A6,'1. INGRESOS'!$B:$B,E$3) | F6: =SUMIFS('1. INGRESOS'!$E:$E,'1. INGRESOS'!$I:$I,$A6,'1. INGRESOS'!$B:$B,F$3) | G6: =SUMIFS('1. INGRESOS'!$E:$E,'1. INGRESOS'!$I:$I,$A6,'1. INGRESOS'!$B:$B,G$3) | H6: =SUMIFS('1. INGRESOS'!$E:$E,'1. INGRESOS'!$I:$I,$A6,'1. INGRESOS'!$B:$B,H$3) | I6: =SUMIFS('1. INGRESOS'!$E:$E,'1. INGRESOS'!$I:$I,$A6,'1. INGRESOS'!$B:$B,I$3) | J6: =SUMIFS('1. INGRESOS'!$E:$E,'1. INGRESOS'!$I:$I,$A6,'1. INGRESOS'!$B:$B,J$3) | ... Z6: =SUMIFS('1. INGRESOS'!$E:$E,'1. INGRESOS'!$I:$I,$A6,'1. INGRESOS'!$B:$B,Z$3)
A7: 2.3 | B7: Ventas Carrito | C7: =SUMIFS('1. INGRESOS'!$E:$E,'1. INGRESOS'!$I:$I,$A7,'1. INGRESOS'!$B:$B,C$3) | D7: =SUMIFS('1. INGRESOS'!$E:$E,'1. INGRESOS'!$I:$I,$A7,'1. INGRESOS'!$B:$B,D$3) | E7: =SUMIFS('1. INGRESOS'!$E:$E,'1. INGRESOS'!$I:$I,$A7,'1. INGRESOS'!$B:$B,E$3) | F7: =SUMIFS('1. INGRESOS'!$E:$E,'1. INGRESOS'!$I:$I,$A7,'1. INGRESOS'!$B:$B,F$3) | G7: =SUMIFS('1. INGRESOS'!$E:$E,'1. INGRESOS'!$I:$I,$A7,'1. INGRESOS'!$B:$B,G$3) | H7: =SUMIFS('1. INGRESOS'!$E:$E,'1. INGRESOS'!$I:$I,$A7,'1. INGRESOS'!$B:$B,H$3) | I7: =SUMIFS('1. INGRESOS'!$E:$E,'1. INGRESOS'!$I:$I,$A7,'1. INGRESOS'!$B:$B,I$3) | J7: =SUMIFS('1. INGRESOS'!$E:$E,'1. INGRESOS'!$I:$I,$A7,'1. INGRESOS'!$B:$B,J$3) | ... Z7: =SUMIFS('1. INGRESOS'!$E:$E,'1. INGRESOS'!$I:$I,$A7,'1. INGRESOS'!$B:$B,Z$3)
A8: 2.4 | B8: Ventas Ferias | C8: =SUMIFS('1. INGRESOS'!$E:$E,'1. INGRESOS'!$I:$I,$A8,'1. INGRESOS'!$B:$B,C$3) | D8: =SUMIFS('1. INGRESOS'!$E:$E,'1. INGRESOS'!$I:$I,$A8,'1. INGRESOS'!$B:$B,D$3) | E8: =SUMIFS('1. INGRESOS'!$E:$E,'1. INGRESOS'!$I:$I,$A8,'1. INGRESOS'!$B:$B,E$3) | F8: =SUMIFS('1. INGRESOS'!$E:$E,'1. INGRESOS'!$I:$I,$A8,'1. INGRESOS'!$B:$B,F$3) | G8: =SUMIFS('1. INGRESOS'!$E:$E,'1. INGRESOS'!$I:$I,$A8,'1. INGRESOS'!$B:$B,G$3) | H8: =SUMIFS('1. INGRESOS'!$E:$E,'1. INGRESOS'!$I:$I,$A8,'1. INGRESOS'!$B:$B,H$3) | I8: =SUMIFS('1. INGRESOS'!$E:$E,'1. INGRESOS'!$I:$I,$A8,'1. INGRESOS'!$B:$B,I$3) | J8: =SUMIFS('1. INGRESOS'!$E:$E,'1. INGRESOS'!$I:$I,$A8,'1. INGRESOS'!$B:$B,J$3) | ... Z8: =SUMIFS('1. INGRESOS'!$E:$E,'1. INGRESOS'!$I:$I,$A8,'1. INGRESOS'!$B:$B,Z$3)
A9: 2.5 | B9: Ventas Delivery Apps | C9: =SUMIFS('1. INGRESOS'!$E:$E,'1. INGRESOS'!$I:$I,$A9,'1. INGRESOS'!$B:$B,C$3) | D9: =SUMIFS('1. INGRESOS'!$E:$E,'1. INGRESOS'!$I:$I,$A9,'1. INGRESOS'!$B:$B,D$3) | E9: =SUMIFS('1. INGRESOS'!$E:$E,'1. INGRESOS'!$I:$I,$A9,'1. INGRESOS'!$B:$B,E$3) | F9: =SUMIFS('1. INGRESOS'!$E:$E,'1. INGRESOS'!$I:$I,$A9,'1. INGRESOS'!$B:$B,F$3) | G9: =SUMIFS('1. INGRESOS'!$E:$E,'1. INGRESOS'!$I:$I,$A9,'1. INGRESOS'!$B:$B,G$3) | H9: =SUMIFS('1. INGRESOS'!$E:$E,'1. INGRESOS'!$I:$I,$A9,'1. INGRESOS'!$B:$B,H$3) | I9: =SUMIFS('1. INGRESOS'!$E:$E,'1. INGRESOS'!$I:$I,$A9,'1. INGRESOS'!$B:$B,I$3) | J9: =SUMIFS('1. INGRESOS'!$E:$E,'1. INGRESOS'!$I:$I,$A9,'1. INGRESOS'!$B:$B,J$3) | ... Z9: =SUMIFS('1. INGRESOS'!$E:$E,'1. INGRESOS'!$I:$I,$A9,'1. INGRESOS'!$B:$B,Z$3)
A10: 2.6 | B10: Otros Ingresos | C10: =SUMIFS('1. INGRESOS'!$E:$E,'1. INGRESOS'!$I:$I,$A10,'1. INGRESOS'!$B:$B,C$3) | D10: =SUMIFS('1. INGRESOS'!$E:$E,'1. INGRESOS'!$I:$I,$A10,'1. INGRESOS'!$B:$B,D$3) | E10: =SUMIFS('1. INGRESOS'!$E:$E,'1. INGRESOS'!$I:$I,$A10,'1. INGRESOS'!$B:$B,E$3) | F10: =SUMIFS('1. INGRESOS'!$E:$E,'1. INGRESOS'!$I:$I,$A10,'1. INGRESOS'!$B:$B,F$3) | G10: =SUMIFS('1. INGRESOS'!$E:$E,'1. INGRESOS'!$I:$I,$A10,'1. INGRESOS'!$B:$B,G$3) | H10: =SUMIFS('1. INGRESOS'!$E:$E,'1. INGRESOS'!$I:$I,$A10,'1. INGRESOS'!$B:$B,H$3) | I10: =SUMIFS('1. INGRESOS'!$E:$E,'1. INGRESOS'!$I:$I,$A10,'1. INGRESOS'!$B:$B,I$3) | J10: =SUMIFS('1. INGRESOS'!$E:$E,'1. INGRESOS'!$I:$I,$A10,'1. INGRESOS'!$B:$B,J$3) | ... Z10: =SUMIFS('1. INGRESOS'!$E:$E,'1. INGRESOS'!$I:$I,$A10,'1. INGRESOS'!$B:$B,Z$3)
A11: 2.7 | B11: Descuentos y devoluciones | C11: =SUMIFS('1. INGRESOS'!$E:$E,'1. INGRESOS'!$I:$I,$A11,'1. INGRESOS'!$B:$B,C$3) | D11: =SUMIFS('1. INGRESOS'!$E:$E,'1. INGRESOS'!$I:$I,$A11,'1. INGRESOS'!$B:$B,D$3) | E11: =SUMIFS('1. INGRESOS'!$E:$E,'1. INGRESOS'!$I:$I,$A11,'1. INGRESOS'!$B:$B,E$3) | F11: =SUMIFS('1. INGRESOS'!$E:$E,'1. INGRESOS'!$I:$I,$A11,'1. INGRESOS'!$B:$B,F$3) | G11: =SUMIFS('1. INGRESOS'!$E:$E,'1. INGRESOS'!$I:$I,$A11,'1. INGRESOS'!$B:$B,G$3) | H11: =SUMIFS('1. INGRESOS'!$E:$E,'1. INGRESOS'!$I:$I,$A11,'1. INGRESOS'!$B:$B,H$3) | I11: =SUMIFS('1. INGRESOS'!$E:$E,'1. INGRESOS'!$I:$I,$A11,'1. INGRESOS'!$B:$B,I$3) | J11: =SUMIFS('1. INGRESOS'!$E:$E,'1. INGRESOS'!$I:$I,$A11,'1. INGRESOS'!$B:$B,J$3) | ... Z11: =SUMIFS('1. INGRESOS'!$E:$E,'1. INGRESOS'!$I:$I,$A11,'1. INGRESOS'!$B:$B,Z$3)
A12: TOTAL INGRESOS | C12: =SUM(C5:C10) | D12: =SUM(D5:D10) | E12: =SUM(E5:E10) | F12: =SUM(F5:F10) | G12: =SUM(G5:G10) | H12: =SUM(H5:H10) | I12: =SUM(I5:I10) | J12: =SUM(J5:J10) | ... Z12: =SUM(Z5:Z10)
A14: CC1 | B14: Costos de Producto | C14: =+SUBTOTAL(9,C15:C17) | D14: =+SUBTOTAL(9,D15:D17) | E14: =+SUBTOTAL(9,E15:E17) | F14: =+SUBTOTAL(9,F15:F17) | G14: =+SUBTOTAL(9,G15:G17) | H14: =+SUBTOTAL(9,H15:H17) | I14: =+SUBTOTAL(9,I15:I17) | J14: =+SUBTOTAL(9,J15:J17) | ... Z14: =+SUBTOTAL(9,Z15:Z17)
A15: 1.1.1 | B15: Ingredientes | C15: =SUMIFS('2. EGRESOS'!$E:$E,'2. EGRESOS'!$K:$K,$A15,'2. EGRESOS'!$B:$B,C$3) | D15: =SUMIFS('2. EGRESOS'!$E:$E,'2. EGRESOS'!$K:$K,$A15,'2. EGRESOS'!$B:$B,D$3) | E15: =SUMIFS('2. EGRESOS'!$E:$E,'2. EGRESOS'!$K:$K,$A15,'2. EGRESOS'!$B:$B,E$3) | F15: =SUMIFS('2. EGRESOS'!$E:$E,'2. EGRESOS'!$K:$K,$A15,'2. EGRESOS'!$B:$B,F$3) | G15: =SUMIFS('2. EGRESOS'!$E:$E,'2. EGRESOS'!$K:$K,$A15,'2. EGRESOS'!$B:$B,G$3) | H15: =SUMIFS('2. EGRESOS'!$E:$E,'2. EGRESOS'!$K:$K,$A15,'2. EGRESOS'!$B:$B,H$3) | I15: =SUMIFS('2. EGRESOS'!$E:$E,'2. EGRESOS'!$K:$K,$A15,'2. EGRESOS'!$B:$B,I$3) | J15: =SUMIFS('2. EGRESOS'!$E:$E,'2. EGRESOS'!$K:$K,$A15,'2. EGRESOS'!$B:$B,J$3) | ... Z15: =SUMIFS('2. EGRESOS'!$E:$E,'2. EGRESOS'!$K:$K,$A15,'2. EGRESOS'!$B:$B,Z$3)
A16: 1.1.2 | B16: Packaging | C16: =SUMIFS('2. EGRESOS'!$E:$E,'2. EGRESOS'!$K:$K,$A16,'2. EGRESOS'!$B:$B,C$3) | D16: =SUMIFS('2. EGRESOS'!$E:$E,'2. EGRESOS'!$K:$K,$A16,'2. EGRESOS'!$B:$B,D$3) | E16: =SUMIFS('2. EGRESOS'!$E:$E,'2. EGRESOS'!$K:$K,$A16,'2. EGRESOS'!$B:$B,E$3) | F16: =SUMIFS('2. EGRESOS'!$E:$E,'2. EGRESOS'!$K:$K,$A16,'2. EGRESOS'!$B:$B,F$3) | G16: =SUMIFS('2. EGRESOS'!$E:$E,'2. EGRESOS'!$K:$K,$A16,'2. EGRESOS'!$B:$B,G$3) | H16: =SUMIFS('2. EGRESOS'!$E:$E,'2. EGRESOS'!$K:$K,$A16,'2. EGRESOS'!$B:$B,H$3) | I16: =SUMIFS('2. EGRESOS'!$E:$E,'2. EGRESOS'!$K:$K,$A16,'2. EGRESOS'!$B:$B,I$3) | J16: =SUMIFS('2. EGRESOS'!$E:$E,'2. EGRESOS'!$K:$K,$A16,'2. EGRESOS'!$B:$B,J$3) | ... Z16: =SUMIFS('2. EGRESOS'!$E:$E,'2. EGRESOS'!$K:$K,$A16,'2. EGRESOS'!$B:$B,Z$3)
A17: 1.1.3 | B17: Equipamiento de cocina | C17: =SUMIFS('2. EGRESOS'!$E:$E,'2. EGRESOS'!$K:$K,$A17,'2. EGRESOS'!$B:$B,C$3) | D17: =SUMIFS('2. EGRESOS'!$E:$E,'2. EGRESOS'!$K:$K,$A17,'2. EGRESOS'!$B:$B,D$3) | E17: =SUMIFS('2. EGRESOS'!$E:$E,'2. EGRESOS'!$K:$K,$A17,'2. EGRESOS'!$B:$B,E$3) | F17: =SUMIFS('2. EGRESOS'!$E:$E,'2. EGRESOS'!$K:$K,$A17,'2. EGRESOS'!$B:$B,F$3) | G17: =SUMIFS('2. EGRESOS'!$E:$E,'2. EGRESOS'!$K:$K,$A17,'2. EGRESOS'!$B:$B,G$3) | H17: =SUMIFS('2. EGRESOS'!$E:$E,'2. EGRESOS'!$K:$K,$A17,'2. EGRESOS'!$B:$B,H$3) | I17: =SUMIFS('2. EGRESOS'!$E:$E,'2. EGRESOS'!$K:$K,$A17,'2. EGRESOS'!$B:$B,I$3) | J17: =SUMIFS('2. EGRESOS'!$E:$E,'2. EGRESOS'!$K:$K,$A17,'2. EGRESOS'!$B:$B,J$3) | ... Z17: =SUMIFS('2. EGRESOS'!$E:$E,'2. EGRESOS'!$K:$K,$A17,'2. EGRESOS'!$B:$B,Z$3)
A18: CC2 | B18: Sueldos y RRHH | C18: =+SUBTOTAL(9,C19:C23) | D18: =+SUBTOTAL(9,D19:D23) | E18: =+SUBTOTAL(9,E19:E23) | F18: =+SUBTOTAL(9,F19:F23) | G18: =+SUBTOTAL(9,G19:G23) | H18: =+SUBTOTAL(9,H19:H23) | I18: =+SUBTOTAL(9,I19:I23) | J18: =+SUBTOTAL(9,J19:J23) | ... Z18: =+SUBTOTAL(9,Z19:Z23)
A19: 1.2.1 | B19: Sueldos con Contrato | C19: =SUMIFS('2. EGRESOS'!$E:$E,'2. EGRESOS'!$K:$K,$A19,'2. EGRESOS'!$B:$B,C$3) | D19: =SUMIFS('2. EGRESOS'!$E:$E,'2. EGRESOS'!$K:$K,$A19,'2. EGRESOS'!$B:$B,D$3) | E19: =SUMIFS('2. EGRESOS'!$E:$E,'2. EGRESOS'!$K:$K,$A19,'2. EGRESOS'!$B:$B,E$3) | F19: =SUMIFS('2. EGRESOS'!$E:$E,'2. EGRESOS'!$K:$K,$A19,'2. EGRESOS'!$B:$B,F$3) | G19: =SUMIFS('2. EGRESOS'!$E:$E,'2. EGRESOS'!$K:$K,$A19,'2. EGRESOS'!$B:$B,G$3) | H19: =SUMIFS('2. EGRESOS'!$E:$E,'2. EGRESOS'!$K:$K,$A19,'2. EGRESOS'!$B:$B,H$3) | I19: =SUMIFS('2. EGRESOS'!$E:$E,'2. EGRESOS'!$K:$K,$A19,'2. EGRESOS'!$B:$B,I$3) | J19: =SUMIFS('2. EGRESOS'!$E:$E,'2. EGRESOS'!$K:$K,$A19,'2. EGRESOS'!$B:$B,J$3) | ... Z19: =SUMIFS('2. EGRESOS'!$E:$E,'2. EGRESOS'!$K:$K,$A19,'2. EGRESOS'!$B:$B,Z$3)
A20: 1.2.2 | B20: Honorarios | C20: =SUMIFS('2. EGRESOS'!$E:$E,'2. EGRESOS'!$K:$K,$A20,'2. EGRESOS'!$B:$B,C$3) | D20: =SUMIFS('2. EGRESOS'!$E:$E,'2. EGRESOS'!$K:$K,$A20,'2. EGRESOS'!$B:$B,D$3) | E20: =SUMIFS('2. EGRESOS'!$E:$E,'2. EGRESOS'!$K:$K,$A20,'2. EGRESOS'!$B:$B,E$3) | F20: =SUMIFS('2. EGRESOS'!$E:$E,'2. EGRESOS'!$K:$K,$A20,'2. EGRESOS'!$B:$B,F$3) | G20: =SUMIFS('2. EGRESOS'!$E:$E,'2. EGRESOS'!$K:$K,$A20,'2. EGRESOS'!$B:$B,G$3) | H20: =SUMIFS('2. EGRESOS'!$E:$E,'2. EGRESOS'!$K:$K,$A20,'2. EGRESOS'!$B:$B,H$3) | I20: =SUMIFS('2. EGRESOS'!$E:$E,'2. EGRESOS'!$K:$K,$A20,'2. EGRESOS'!$B:$B,I$3) | J20: =SUMIFS('2. EGRESOS'!$E:$E,'2. EGRESOS'!$K:$K,$A20,'2. EGRESOS'!$B:$B,J$3) | ... Z20: =SUMIFS('2. EGRESOS'!$E:$E,'2. EGRESOS'!$K:$K,$A20,'2. EGRESOS'!$B:$B,Z$3)
A21: 1.2.3 | B21: Asesoria Contable | C21: =SUMIFS('2. EGRESOS'!$E:$E,'2. EGRESOS'!$K:$K,$A21,'2. EGRESOS'!$B:$B,C$3) | D21: =SUMIFS('2. EGRESOS'!$E:$E,'2. EGRESOS'!$K:$K,$A21,'2. EGRESOS'!$B:$B,D$3) | E21: =SUMIFS('2. EGRESOS'!$E:$E,'2. EGRESOS'!$K:$K,$A21,'2. EGRESOS'!$B:$B,E$3) | F21: =SUMIFS('2. EGRESOS'!$E:$E,'2. EGRESOS'!$K:$K,$A21,'2. EGRESOS'!$B:$B,F$3) | G21: =SUMIFS('2. EGRESOS'!$E:$E,'2. EGRESOS'!$K:$K,$A21,'2. EGRESOS'!$B:$B,G$3) | H21: =SUMIFS('2. EGRESOS'!$E:$E,'2. EGRESOS'!$K:$K,$A21,'2. EGRESOS'!$B:$B,H$3) | I21: =SUMIFS('2. EGRESOS'!$E:$E,'2. EGRESOS'!$K:$K,$A21,'2. EGRESOS'!$B:$B,I$3) | J21: =SUMIFS('2. EGRESOS'!$E:$E,'2. EGRESOS'!$K:$K,$A21,'2. EGRESOS'!$B:$B,J$3) | ... Z21: =SUMIFS('2. EGRESOS'!$E:$E,'2. EGRESOS'!$K:$K,$A21,'2. EGRESOS'!$B:$B,Z$3)
A22: 1.2.4 | B22: Uniformes Personal | C22: =SUMIFS('2. EGRESOS'!$E:$E,'2. EGRESOS'!$K:$K,$A22,'2. EGRESOS'!$B:$B,C$3) | D22: =SUMIFS('2. EGRESOS'!$E:$E,'2. EGRESOS'!$K:$K,$A22,'2. EGRESOS'!$B:$B,D$3) | E22: =SUMIFS('2. EGRESOS'!$E:$E,'2. EGRESOS'!$K:$K,$A22,'2. EGRESOS'!$B:$B,E$3) | F22: =SUMIFS('2. EGRESOS'!$E:$E,'2. EGRESOS'!$K:$K,$A22,'2. EGRESOS'!$B:$B,F$3) | G22: =SUMIFS('2. EGRESOS'!$E:$E,'2. EGRESOS'!$K:$K,$A22,'2. EGRESOS'!$B:$B,G$3) | H22: =SUMIFS('2. EGRESOS'!$E:$E,'2. EGRESOS'!$K:$K,$A22,'2. EGRESOS'!$B:$B,H$3) | I22: =SUMIFS('2. EGRESOS'!$E:$E,'2. EGRESOS'!$K:$K,$A22,'2. EGRESOS'!$B:$B,I$3) | J22: =SUMIFS('2. EGRESOS'!$E:$E,'2. EGRESOS'!$K:$K,$A22,'2. EGRESOS'!$B:$B,J$3) | ... Z22: =SUMIFS('2. EGRESOS'!$E:$E,'2. EGRESOS'!$K:$K,$A22,'2. EGRESOS'!$B:$B,Z$3)
A23: 1.2.5 | B23: Prestamos Personal | C23: =SUMIFS('2. EGRESOS'!$E:$E,'2. EGRESOS'!$K:$K,$A23,'2. EGRESOS'!$B:$B,C$3) | D23: =SUMIFS('2. EGRESOS'!$E:$E,'2. EGRESOS'!$K:$K,$A23,'2. EGRESOS'!$B:$B,D$3) | E23: =SUMIFS('2. EGRESOS'!$E:$E,'2. EGRESOS'!$K:$K,$A23,'2. EGRESOS'!$B:$B,E$3) | F23: =SUMIFS('2. EGRESOS'!$E:$E,'2. EGRESOS'!$K:$K,$A23,'2. EGRESOS'!$B:$B,F$3) | G23: =SUMIFS('2. EGRESOS'!$E:$E,'2. EGRESOS'!$K:$K,$A23,'2. EGRESOS'!$B:$B,G$3) | H23: =SUMIFS('2. EGRESOS'!$E:$E,'2. EGRESOS'!$K:$K,$A23,'2. EGRESOS'!$B:$B,H$3) | I23: =SUMIFS('2. EGRESOS'!$E:$E,'2. EGRESOS'!$K:$K,$A23,'2. EGRESOS'!$B:$B,I$3) | J23: =SUMIFS('2. EGRESOS'!$E:$E,'2. EGRESOS'!$K:$K,$A23,'2. EGRESOS'!$B:$B,J$3) | ... Z23: =SUMIFS('2. EGRESOS'!$E:$E,'2. EGRESOS'!$K:$K,$A23,'2. EGRESOS'!$B:$B,Z$3)
A24: CC3 | B24: Infraestructura | C24: =+SUBTOTAL(9,C25:C34) | D24: =+SUBTOTAL(9,D25:D34) | E24: =+SUBTOTAL(9,E25:E34) | F24: =+SUBTOTAL(9,F25:F34) | G24: =+SUBTOTAL(9,G25:G34) | H24: =+SUBTOTAL(9,H25:H34) | I24: =+SUBTOTAL(9,I25:I34) | J24: =+SUBTOTAL(9,J25:J34) | ... Z24: =+SUBTOTAL(9,Z25:Z34)
A25: 1.3.1 | B25: Arriendo Local | C25: =SUMIFS('2. EGRESOS'!$E:$E,'2. EGRESOS'!$K:$K,$A25,'2. EGRESOS'!$B:$B,C$3) | D25: =SUMIFS('2. EGRESOS'!$E:$E,'2. EGRESOS'!$K:$K,$A25,'2. EGRESOS'!$B:$B,D$3) | E25: =SUMIFS('2. EGRESOS'!$E:$E,'2. EGRESOS'!$K:$K,$A25,'2. EGRESOS'!$B:$B,E$3) | F25: =SUMIFS('2. EGRESOS'!$E:$E,'2. EGRESOS'!$K:$K,$A25,'2. EGRESOS'!$B:$B,F$3) | G25: =SUMIFS('2. EGRESOS'!$E:$E,'2. EGRESOS'!$K:$K,$A25,'2. EGRESOS'!$B:$B,G$3) | H25: =SUMIFS('2. EGRESOS'!$E:$E,'2. EGRESOS'!$K:$K,$A25,'2. EGRESOS'!$B:$B,H$3) | I25: =SUMIFS('2. EGRESOS'!$E:$E,'2. EGRESOS'!$K:$K,$A25,'2. EGRESOS'!$B:$B,I$3) | J25: =SUMIFS('2. EGRESOS'!$E:$E,'2. EGRESOS'!$K:$K,$A25,'2. EGRESOS'!$B:$B,J$3) | ... Z25: =SUMIFS('2. EGRESOS'!$E:$E,'2. EGRESOS'!$K:$K,$A25,'2. EGRESOS'!$B:$B,Z$3)
A26: 1.3.2 | B26: Agua | C26: =SUMIFS('2. EGRESOS'!$E:$E,'2. EGRESOS'!$K:$K,$A26,'2. EGRESOS'!$B:$B,C$3) | D26: =SUMIFS('2. EGRESOS'!$E:$E,'2. EGRESOS'!$K:$K,$A26,'2. EGRESOS'!$B:$B,D$3) | E26: =SUMIFS('2. EGRESOS'!$E:$E,'2. EGRESOS'!$K:$K,$A26,'2. EGRESOS'!$B:$B,E$3) | F26: =SUMIFS('2. EGRESOS'!$E:$E,'2. EGRESOS'!$K:$K,$A26,'2. EGRESOS'!$B:$B,F$3) | G26: =SUMIFS('2. EGRESOS'!$E:$E,'2. EGRESOS'!$K:$K,$A26,'2. EGRESOS'!$B:$B,G$3) | H26: =SUMIFS('2. EGRESOS'!$E:$E,'2. EGRESOS'!$K:$K,$A26,'2. EGRESOS'!$B:$B,H$3) | I26: =SUMIFS('2. EGRESOS'!$E:$E,'2. EGRESOS'!$K:$K,$A26,'2. EGRESOS'!$B:$B,I$3) | J26: =SUMIFS('2. EGRESOS'!$E:$E,'2. EGRESOS'!$K:$K,$A26,'2. EGRESOS'!$B:$B,J$3) | ... Z26: =SUMIFS('2. EGRESOS'!$E:$E,'2. EGRESOS'!$K:$K,$A26,'2. EGRESOS'!$B:$B,Z$3)
A27: 1.3.3 | B27: Luz | C27: =SUMIFS('2. EGRESOS'!$E:$E,'2. EGRESOS'!$K:$K,$A27,'2. EGRESOS'!$B:$B,C$3) | D27: =SUMIFS('2. EGRESOS'!$E:$E,'2. EGRESOS'!$K:$K,$A27,'2. EGRESOS'!$B:$B,D$3) | E27: =SUMIFS('2. EGRESOS'!$E:$E,'2. EGRESOS'!$K:$K,$A27,'2. EGRESOS'!$B:$B,E$3) | F27: =SUMIFS('2. EGRESOS'!$E:$E,'2. EGRESOS'!$K:$K,$A27,'2. EGRESOS'!$B:$B,F$3) | G27: =SUMIFS('2. EGRESOS'!$E:$E,'2. EGRESOS'!$K:$K,$A27,'2. EGRESOS'!$B:$B,G$3) | H27: =SUMIFS('2. EGRESOS'!$E:$E,'2. EGRESOS'!$K:$K,$A27,'2. EGRESOS'!$B:$B,H$3) | I27: =SUMIFS('2. EGRESOS'!$E:$E,'2. EGRESOS'!$K:$K,$A27,'2. EGRESOS'!$B:$B,I$3) | J27: =SUMIFS('2. EGRESOS'!$E:$E,'2. EGRESOS'!$K:$K,$A27,'2. EGRESOS'!$B:$B,J$3) | ... Z27: =SUMIFS('2. EGRESOS'!$E:$E,'2. EGRESOS'!$K:$K,$A27,'2. EGRESOS'!$B:$B,Z$3)
A28: 1.3.4 | B28: Gas | C28: =SUMIFS('2. EGRESOS'!$E:$E,'2. EGRESOS'!$K:$K,$A28,'2. EGRESOS'!$B:$B,C$3) | D28: =SUMIFS('2. EGRESOS'!$E:$E,'2. EGRESOS'!$K:$K,$A28,'2. EGRESOS'!$B:$B,D$3) | E28: =SUMIFS('2. EGRESOS'!$E:$E,'2. EGRESOS'!$K:$K,$A28,'2. EGRESOS'!$B:$B,E$3) | F28: =SUMIFS('2. EGRESOS'!$E:$E,'2. EGRESOS'!$K:$K,$A28,'2. EGRESOS'!$B:$B,F$3) | G28: =SUMIFS('2. EGRESOS'!$E:$E,'2. EGRESOS'!$K:$K,$A28,'2. EGRESOS'!$B:$B,G$3) | H28: =SUMIFS('2. EGRESOS'!$E:$E,'2. EGRESOS'!$K:$K,$A28,'2. EGRESOS'!$B:$B,H$3) | I28: =SUMIFS('2. EGRESOS'!$E:$E,'2. EGRESOS'!$K:$K,$A28,'2. EGRESOS'!$B:$B,I$3) | J28: =SUMIFS('2. EGRESOS'!$E:$E,'2. EGRESOS'!$K:$K,$A28,'2. EGRESOS'!$B:$B,J$3) | ... Z28: =SUMIFS('2. EGRESOS'!$E:$E,'2. EGRESOS'!$K:$K,$A28,'2. EGRESOS'!$B:$B,Z$3)
A29: 1.3.5 | B29: Telecomunicaciones | C29: =SUMIFS('2. EGRESOS'!$E:$E,'2. EGRESOS'!$K:$K,$A29,'2. EGRESOS'!$B:$B,C$3) | D29: =SUMIFS('2. EGRESOS'!$E:$E,'2. EGRESOS'!$K:$K,$A29,'2. EGRESOS'!$B:$B,D$3) | E29: =SUMIFS('2. EGRESOS'!$E:$E,'2. EGRESOS'!$K:$K,$A29,'2. EGRESOS'!$B:$B,E$3) | F29: =SUMIFS('2. EGRESOS'!$E:$E,'2. EGRESOS'!$K:$K,$A29,'2. EGRESOS'!$B:$B,F$3) | G29: =SUMIFS('2. EGRESOS'!$E:$E,'2. EGRESOS'!$K:$K,$A29,'2. EGRESOS'!$B:$B,G$3) | H29: =SUMIFS('2. EGRESOS'!$E:$E,'2. EGRESOS'!$K:$K,$A29,'2. EGRESOS'!$B:$B,H$3) | I29: =SUMIFS('2. EGRESOS'!$E:$E,'2. EGRESOS'!$K:$K,$A29,'2. EGRESOS'!$B:$B,I$3) | J29: =SUMIFS('2. EGRESOS'!$E:$E,'2. EGRESOS'!$K:$K,$A29,'2. EGRESOS'!$B:$B,J$3) | ... Z29: =SUMIFS('2. EGRESOS'!$E:$E,'2. EGRESOS'!$K:$K,$A29,'2. EGRESOS'!$B:$B,Z$3)
A30: 1.3.6 | B30: Mantenciones | C30: =SUMIFS('2. EGRESOS'!$E:$E,'2. EGRESOS'!$K:$K,$A30,'2. EGRESOS'!$B:$B,C$3) | D30: =SUMIFS('2. EGRESOS'!$E:$E,'2. EGRESOS'!$K:$K,$A30,'2. EGRESOS'!$B:$B,D$3) | E30: =SUMIFS('2. EGRESOS'!$E:$E,'2. EGRESOS'!$K:$K,$A30,'2. EGRESOS'!$B:$B,E$3) | F30: =SUMIFS('2. EGRESOS'!$E:$E,'2. EGRESOS'!$K:$K,$A30,'2. EGRESOS'!$B:$B,F$3) | G30: =SUMIFS('2. EGRESOS'!$E:$E,'2. EGRESOS'!$K:$K,$A30,'2. EGRESOS'!$B:$B,G$3) | H30: =SUMIFS('2. EGRESOS'!$E:$E,'2. EGRESOS'!$K:$K,$A30,'2. EGRESOS'!$B:$B,H$3) | I30: =SUMIFS('2. EGRESOS'!$E:$E,'2. EGRESOS'!$K:$K,$A30,'2. EGRESOS'!$B:$B,I$3) | J30: =SUMIFS('2. EGRESOS'!$E:$E,'2. EGRESOS'!$K:$K,$A30,'2. EGRESOS'!$B:$B,J$3) | ... Z30: =SUMIFS('2. EGRESOS'!$E:$E,'2. EGRESOS'!$K:$K,$A30,'2. EGRESOS'!$B:$B,Z$3)
A31: 1.3.7 | B31: Fumigaciones | C31: =SUMIFS('2. EGRESOS'!$E:$E,'2. EGRESOS'!$K:$K,$A31,'2. EGRESOS'!$B:$B,C$3) | D31: =SUMIFS('2. EGRESOS'!$E:$E,'2. EGRESOS'!$K:$K,$A31,'2. EGRESOS'!$B:$B,D$3) | E31: =SUMIFS('2. EGRESOS'!$E:$E,'2. EGRESOS'!$K:$K,$A31,'2. EGRESOS'!$B:$B,E$3) | F31: =SUMIFS('2. EGRESOS'!$E:$E,'2. EGRESOS'!$K:$K,$A31,'2. EGRESOS'!$B:$B,F$3) | G31: =SUMIFS('2. EGRESOS'!$E:$E,'2. EGRESOS'!$K:$K,$A31,'2. EGRESOS'!$B:$B,G$3) | H31: =SUMIFS('2. EGRESOS'!$E:$E,'2. EGRESOS'!$K:$K,$A31,'2. EGRESOS'!$B:$B,H$3) | I31: =SUMIFS('2. EGRESOS'!$E:$E,'2. EGRESOS'!$K:$K,$A31,'2. EGRESOS'!$B:$B,I$3) | J31: =SUMIFS('2. EGRESOS'!$E:$E,'2. EGRESOS'!$K:$K,$A31,'2. EGRESOS'!$B:$B,J$3) | ... Z31: =SUMIFS('2. EGRESOS'!$E:$E,'2. EGRESOS'!$K:$K,$A31,'2. EGRESOS'!$B:$B,Z$3)
A32: 1.3.8 | B32: Limpieza y Aseo | C32: =SUMIFS('2. EGRESOS'!$E:$E,'2. EGRESOS'!$K:$K,$A32,'2. EGRESOS'!$B:$B,C$3) | D32: =SUMIFS('2. EGRESOS'!$E:$E,'2. EGRESOS'!$K:$K,$A32,'2. EGRESOS'!$B:$B,D$3) | E32: =SUMIFS('2. EGRESOS'!$E:$E,'2. EGRESOS'!$K:$K,$A32,'2. EGRESOS'!$B:$B,E$3) | F32: =SUMIFS('2. EGRESOS'!$E:$E,'2. EGRESOS'!$K:$K,$A32,'2. EGRESOS'!$B:$B,F$3) | G32: =SUMIFS('2. EGRESOS'!$E:$E,'2. EGRESOS'!$K:$K,$A32,'2. EGRESOS'!$B:$B,G$3) | H32: =SUMIFS('2. EGRESOS'!$E:$E,'2. EGRESOS'!$K:$K,$A32,'2. EGRESOS'!$B:$B,H$3) | I32: =SUMIFS('2. EGRESOS'!$E:$E,'2. EGRESOS'!$K:$K,$A32,'2. EGRESOS'!$B:$B,I$3) | J32: =SUMIFS('2. EGRESOS'!$E:$E,'2. EGRESOS'!$K:$K,$A32,'2. EGRESOS'!$B:$B,J$3) | ... Z32: =SUMIFS('2. EGRESOS'!$E:$E,'2. EGRESOS'!$K:$K,$A32,'2. EGRESOS'!$B:$B,Z$3)
A33: 1.3.9 | B33: Seguridad | C33: =SUMIFS('2. EGRESOS'!$E:$E,'2. EGRESOS'!$K:$K,$A33,'2. EGRESOS'!$B:$B,C$3) | D33: =SUMIFS('2. EGRESOS'!$E:$E,'2. EGRESOS'!$K:$K,$A33,'2. EGRESOS'!$B:$B,D$3) | E33: =SUMIFS('2. EGRESOS'!$E:$E,'2. EGRESOS'!$K:$K,$A33,'2. EGRESOS'!$B:$B,E$3) | F33: =SUMIFS('2. EGRESOS'!$E:$E,'2. EGRESOS'!$K:$K,$A33,'2. EGRESOS'!$B:$B,F$3) | G33: =SUMIFS('2. EGRESOS'!$E:$E,'2. EGRESOS'!$K:$K,$A33,'2. EGRESOS'!$B:$B,G$3) | H33: =SUMIFS('2. EGRESOS'!$E:$E,'2. EGRESOS'!$K:$K,$A33,'2. EGRESOS'!$B:$B,H$3) | I33: =SUMIFS('2. EGRESOS'!$E:$E,'2. EGRESOS'!$K:$K,$A33,'2. EGRESOS'!$B:$B,I$3) | J33: =SUMIFS('2. EGRESOS'!$E:$E,'2. EGRESOS'!$K:$K,$A33,'2. EGRESOS'!$B:$B,J$3) | ... Z33: =SUMIFS('2. EGRESOS'!$E:$E,'2. EGRESOS'!$K:$K,$A33,'2. EGRESOS'!$B:$B,Z$3)
A34: 1.3.10 | B34: Equipamiento Local | C34: =SUMIFS('2. EGRESOS'!$E:$E,'2. EGRESOS'!$K:$K,$A34,'2. EGRESOS'!$B:$B,C$3) | D34: =SUMIFS('2. EGRESOS'!$E:$E,'2. EGRESOS'!$K:$K,$A34,'2. EGRESOS'!$B:$B,D$3) | E34: =SUMIFS('2. EGRESOS'!$E:$E,'2. EGRESOS'!$K:$K,$A34,'2. EGRESOS'!$B:$B,E$3) | F34: =SUMIFS('2. EGRESOS'!$E:$E,'2. EGRESOS'!$K:$K,$A34,'2. EGRESOS'!$B:$B,F$3) | G34: =SUMIFS('2. EGRESOS'!$E:$E,'2. EGRESOS'!$K:$K,$A34,'2. EGRESOS'!$B:$B,G$3) | H34: =SUMIFS('2. EGRESOS'!$E:$E,'2. EGRESOS'!$K:$K,$A34,'2. EGRESOS'!$B:$B,H$3) | I34: =SUMIFS('2. EGRESOS'!$E:$E,'2. EGRESOS'!$K:$K,$A34,'2. EGRESOS'!$B:$B,I$3) | J34: =SUMIFS('2. EGRESOS'!$E:$E,'2. EGRESOS'!$K:$K,$A34,'2. EGRESOS'!$B:$B,J$3) | ... Z34: =SUMIFS('2. EGRESOS'!$E:$E,'2. EGRESOS'!$K:$K,$A34,'2. EGRESOS'!$B:$B,Z$3)
A35: CC4 | B35: Carrito | C35: =+SUBTOTAL(9,C36:C40) | D35: =+SUBTOTAL(9,D36:D40) | E35: =+SUBTOTAL(9,E36:E40) | F35: =+SUBTOTAL(9,F36:F40) | G35: =+SUBTOTAL(9,G36:G40) | H35: =+SUBTOTAL(9,H36:H40) | I35: =+SUBTOTAL(9,I36:I40) | J35: =+SUBTOTAL(9,J36:J40) | ... Z35: =+SUBTOTAL(9,Z36:Z40)
A36: 1.4.1 | B36: Inversión Carro | C36: =SUMIFS('2. EGRESOS'!$E:$E,'2. EGRESOS'!$K:$K,$A36,'2. EGRESOS'!$B:$B,C$3) | D36: =SUMIFS('2. EGRESOS'!$E:$E,'2. EGRESOS'!$K:$K,$A36,'2. EGRESOS'!$B:$B,D$3) | E36: =SUMIFS('2. EGRESOS'!$E:$E,'2. EGRESOS'!$K:$K,$A36,'2. EGRESOS'!$B:$B,E$3) | F36: =SUMIFS('2. EGRESOS'!$E:$E,'2. EGRESOS'!$K:$K,$A36,'2. EGRESOS'!$B:$B,F$3) | G36: =SUMIFS('2. EGRESOS'!$E:$E,'2. EGRESOS'!$K:$K,$A36,'2. EGRESOS'!$B:$B,G$3) | H36: =SUMIFS('2. EGRESOS'!$E:$E,'2. EGRESOS'!$K:$K,$A36,'2. EGRESOS'!$B:$B,H$3) | I36: =SUMIFS('2. EGRESOS'!$E:$E,'2. EGRESOS'!$K:$K,$A36,'2. EGRESOS'!$B:$B,I$3) | J36: =SUMIFS('2. EGRESOS'!$E:$E,'2. EGRESOS'!$K:$K,$A36,'2. EGRESOS'!$B:$B,J$3) | ... Z36: =SUMIFS('2. EGRESOS'!$E:$E,'2. EGRESOS'!$K:$K,$A36,'2. EGRESOS'!$B:$B,Z$3)
A37: 1.4.2 | B37: Mantención Carro | C37: =SUMIFS('2. EGRESOS'!$E:$E,'2. EGRESOS'!$K:$K,$A37,'2. EGRESOS'!$B:$B,C$3) | D37: =SUMIFS('2. EGRESOS'!$E:$E,'2. EGRESOS'!$K:$K,$A37,'2. EGRESOS'!$B:$B,D$3) | E37: =SUMIFS('2. EGRESOS'!$E:$E,'2. EGRESOS'!$K:$K,$A37,'2. EGRESOS'!$B:$B,E$3) | F37: =SUMIFS('2. EGRESOS'!$E:$E,'2. EGRESOS'!$K:$K,$A37,'2. EGRESOS'!$B:$B,F$3) | G37: =SUMIFS('2. EGRESOS'!$E:$E,'2. EGRESOS'!$K:$K,$A37,'2. EGRESOS'!$B:$B,G$3) | H37: =SUMIFS('2. EGRESOS'!$E:$E,'2. EGRESOS'!$K:$K,$A37,'2. EGRESOS'!$B:$B,H$3) | I37: =SUMIFS('2. EGRESOS'!$E:$E,'2. EGRESOS'!$K:$K,$A37,'2. EGRESOS'!$B:$B,I$3) | J37: =SUMIFS('2. EGRESOS'!$E:$E,'2. EGRESOS'!$K:$K,$A37,'2. EGRESOS'!$B:$B,J$3) | ... Z37: =SUMIFS('2. EGRESOS'!$E:$E,'2. EGRESOS'!$K:$K,$A37,'2. EGRESOS'!$B:$B,Z$3)
A38: 1.4.3 | B38: Materiales Aseo Carro | C38: =SUMIFS('2. EGRESOS'!$E:$E,'2. EGRESOS'!$K:$K,$A38,'2. EGRESOS'!$B:$B,C$3) | D38: =SUMIFS('2. EGRESOS'!$E:$E,'2. EGRESOS'!$K:$K,$A38,'2. EGRESOS'!$B:$B,D$3) | E38: =SUMIFS('2. EGRESOS'!$E:$E,'2. EGRESOS'!$K:$K,$A38,'2. EGRESOS'!$B:$B,E$3) | F38: =SUMIFS('2. EGRESOS'!$E:$E,'2. EGRESOS'!$K:$K,$A38,'2. EGRESOS'!$B:$B,F$3) | G38: =SUMIFS('2. EGRESOS'!$E:$E,'2. EGRESOS'!$K:$K,$A38,'2. EGRESOS'!$B:$B,G$3) | H38: =SUMIFS('2. EGRESOS'!$E:$E,'2. EGRESOS'!$K:$K,$A38,'2. EGRESOS'!$B:$B,H$3) | I38: =SUMIFS('2. EGRESOS'!$E:$E,'2. EGRESOS'!$K:$K,$A38,'2. EGRESOS'!$B:$B,I$3) | J38: =SUMIFS('2. EGRESOS'!$E:$E,'2. EGRESOS'!$K:$K,$A38,'2. EGRESOS'!$B:$B,J$3) | ... Z38: =SUMIFS('2. EGRESOS'!$E:$E,'2. EGRESOS'!$K:$K,$A38,'2. EGRESOS'!$B:$B,Z$3)
A39: 1.4.4 | B39: Despacho Carro | C39: =SUMIFS('2. EGRESOS'!$E:$E,'2. EGRESOS'!$K:$K,$A39,'2. EGRESOS'!$B:$B,C$3) | D39: =SUMIFS('2. EGRESOS'!$E:$E,'2. EGRESOS'!$K:$K,$A39,'2. EGRESOS'!$B:$B,D$3) | E39: =SUMIFS('2. EGRESOS'!$E:$E,'2. EGRESOS'!$K:$K,$A39,'2. EGRESOS'!$B:$B,E$3) | F39: =SUMIFS('2. EGRESOS'!$E:$E,'2. EGRESOS'!$K:$K,$A39,'2. EGRESOS'!$B:$B,F$3) | G39: =SUMIFS('2. EGRESOS'!$E:$E,'2. EGRESOS'!$K:$K,$A39,'2. EGRESOS'!$B:$B,G$3) | H39: =SUMIFS('2. EGRESOS'!$E:$E,'2. EGRESOS'!$K:$K,$A39,'2. EGRESOS'!$B:$B,H$3) | I39: =SUMIFS('2. EGRESOS'!$E:$E,'2. EGRESOS'!$K:$K,$A39,'2. EGRESOS'!$B:$B,I$3) | J39: =SUMIFS('2. EGRESOS'!$E:$E,'2. EGRESOS'!$K:$K,$A39,'2. EGRESOS'!$B:$B,J$3) | ... Z39: =SUMIFS('2. EGRESOS'!$E:$E,'2. EGRESOS'!$K:$K,$A39,'2. EGRESOS'!$B:$B,Z$3)
A40: 1.4.5 | B40: Sueldos Carro | C40: =SUMIFS('2. EGRESOS'!$E:$E,'2. EGRESOS'!$K:$K,$A40,'2. EGRESOS'!$B:$B,C$3) | D40: =SUMIFS('2. EGRESOS'!$E:$E,'2. EGRESOS'!$K:$K,$A40,'2. EGRESOS'!$B:$B,D$3) | E40: =SUMIFS('2. EGRESOS'!$E:$E,'2. EGRESOS'!$K:$K,$A40,'2. EGRESOS'!$B:$B,E$3) | F40: =SUMIFS('2. EGRESOS'!$E:$E,'2. EGRESOS'!$K:$K,$A40,'2. EGRESOS'!$B:$B,F$3) | G40: =SUMIFS('2. EGRESOS'!$E:$E,'2. EGRESOS'!$K:$K,$A40,'2. EGRESOS'!$B:$B,G$3) | H40: =SUMIFS('2. EGRESOS'!$E:$E,'2. EGRESOS'!$K:$K,$A40,'2. EGRESOS'!$B:$B,H$3) | I40: =SUMIFS('2. EGRESOS'!$E:$E,'2. EGRESOS'!$K:$K,$A40,'2. EGRESOS'!$B:$B,I$3) | J40: =SUMIFS('2. EGRESOS'!$E:$E,'2. EGRESOS'!$K:$K,$A40,'2. EGRESOS'!$B:$B,J$3) | ... Z40: =SUMIFS('2. EGRESOS'!$E:$E,'2. EGRESOS'!$K:$K,$A40,'2. EGRESOS'!$B:$B,Z$3)
A41: CC5 | B41: SAAS | C41: =+SUBTOTAL(9,C42:C43) | D41: =+SUBTOTAL(9,D42:D43) | E41: =+SUBTOTAL(9,E42:E43) | F41: =+SUBTOTAL(9,F42:F43) | G41: =+SUBTOTAL(9,G42:G43) | H41: =+SUBTOTAL(9,H42:H43) | I41: =+SUBTOTAL(9,I42:I43) | J41: =+SUBTOTAL(9,J42:J43) | ... Z41: =+SUBTOTAL(9,Z42:Z43)
...

Sheet KPIs
A1: KPIs — FAIT PAR MARIE | Valores Netos sin IVA | Base: Mes Devengo
A2: Indicador | B2: Ref. | C2: Unidad | D2: Benchmark | E2: 2025-01 | F2: 2025-02 | G2: 2025-03 | H2: 2025-04 | I2: 2025-05 | J2: 2025-06 | K2: 2025-07 | L2: 2025-08 | M2: 2025-09 | N2: 2025-10 | O2: 2025-11 | P2: 2025-12 | Q2: 2026-01 | R2: 2026-02 | S2: 2026-03 | T2: 2026-04 | U2: 2026-05 | V2: 2026-06 | W2: 2026-07 | X2: 2026-08 | Y2: 2026-09 | Z2: 2026-10 | AA2: 2026-11 | AB2: 2026-12 | AC2: Prom. mensual
A4: INGRESOS
A5: Venta Neta Total | C5: $ | E5: =SUMIFS('1. INGRESOS'!$H:$H,'1. INGRESOS'!$B:$B,E$2) | F5: =SUMIFS('1. INGRESOS'!$H:$H,'1. INGRESOS'!$B:$B,F$2) | G5: =SUMIFS('1. INGRESOS'!$H:$H,'1. INGRESOS'!$B:$B,G$2) | H5: =SUMIFS('1. INGRESOS'!$H:$H,'1. INGRESOS'!$B:$B,H$2) | I5: =SUMIFS('1. INGRESOS'!$H:$H,'1. INGRESOS'!$B:$B,I$2) | J5: =SUMIFS('1. INGRESOS'!$H:$H,'1. INGRESOS'!$B:$B,J$2) | K5: =SUMIFS('1. INGRESOS'!$H:$H,'1. INGRESOS'!$B:$B,K$2) | L5: =SUMIFS('1. INGRESOS'!$H:$H,'1. INGRESOS'!$B:$B,L$2) | ... AB5: =SUMIFS('1. INGRESOS'!$H:$H,'1. INGRESOS'!$B:$B,AB$2) | AC5: =IFERROR(AVERAGE(E5:U5),"")
A6: HoReCa | B6: =CANALES!$A$3 | C6: $ | E6: =SUMIFS('1. INGRESOS'!$H:$H,'1. INGRESOS'!$B:$B,E$2,'1. INGRESOS'!$K:$K,$B6) | F6: =SUMIFS('1. INGRESOS'!$H:$H,'1. INGRESOS'!$B:$B,F$2,'1. INGRESOS'!$K:$K,$B6) | G6: =SUMIFS('1. INGRESOS'!$H:$H,'1. INGRESOS'!$B:$B,G$2,'1. INGRESOS'!$K:$K,$B6) | H6: =SUMIFS('1. INGRESOS'!$H:$H,'1. INGRESOS'!$B:$B,H$2,'1. INGRESOS'!$K:$K,$B6) | I6: =SUMIFS('1. INGRESOS'!$H:$H,'1. INGRESOS'!$B:$B,I$2,'1. INGRESOS'!$K:$K,$B6) | J6: =SUMIFS('1. INGRESOS'!$H:$H,'1. INGRESOS'!$B:$B,J$2,'1. INGRESOS'!$K:$K,$B6) | K6: =SUMIFS('1. INGRESOS'!$H:$H,'1. INGRESOS'!$B:$B,K$2,'1. INGRESOS'!$K:$K,$B6) | L6: =SUMIFS('1. INGRESOS'!$H:$H,'1. INGRESOS'!$B:$B,L$2,'1. INGRESOS'!$K:$K,$B6) | ... AB6: =SUMIFS('1. INGRESOS'!$H:$H,'1. INGRESOS'!$B:$B,AB$2,'1. INGRESOS'!$K:$K,$B6) | AC6: =IFERROR(AVERAGE(E6:U6),"")
A7: B2C Boutique | B7: =CANALES!$A$4 | C7: $ | E7: =SUMIFS('1. INGRESOS'!$H:$H,'1. INGRESOS'!$B:$B,E$2,'1. INGRESOS'!$K:$K,$B7) | F7: =SUMIFS('1. INGRESOS'!$H:$H,'1. INGRESOS'!$B:$B,F$2,'1. INGRESOS'!$K:$K,$B7) | G7: =SUMIFS('1. INGRESOS'!$H:$H,'1. INGRESOS'!$B:$B,G$2,'1. INGRESOS'!$K:$K,$B7) | H7: =SUMIFS('1. INGRESOS'!$H:$H,'1. INGRESOS'!$B:$B,H$2,'1. INGRESOS'!$K:$K,$B7) | I7: =SUMIFS('1. INGRESOS'!$H:$H,'1. INGRESOS'!$B:$B,I$2,'1. INGRESOS'!$K:$K,$B7) | J7: =SUMIFS('1. INGRESOS'!$H:$H,'1. INGRESOS'!$B:$B,J$2,'1. INGRESOS'!$K:$K,$B7) | K7: =SUMIFS('1. INGRESOS'!$H:$H,'1. INGRESOS'!$B:$B,K$2,'1. INGRESOS'!$K:$K,$B7) | L7: =SUMIFS('1. INGRESOS'!$H:$H,'1. INGRESOS'!$B:$B,L$2,'1. INGRESOS'!$K:$K,$B7) | ... AB7: =SUMIFS('1. INGRESOS'!$H:$H,'1. INGRESOS'!$B:$B,AB$2,'1. INGRESOS'!$K:$K,$B7) | AC7: =IFERROR(AVERAGE(E7:U7),"")
A8: Delivery Apps | B8: =CANALES!$A$5 | C8: $ | E8: =SUMIFS('1. INGRESOS'!$H:$H,'1. INGRESOS'!$B:$B,E$2,'1. INGRESOS'!$K:$K,$B8) | F8: =SUMIFS('1. INGRESOS'!$H:$H,'1. INGRESOS'!$B:$B,F$2,'1. INGRESOS'!$K:$K,$B8) | G8: =SUMIFS('1. INGRESOS'!$H:$H,'1. INGRESOS'!$B:$B,G$2,'1. INGRESOS'!$K:$K,$B8) | H8: =SUMIFS('1. INGRESOS'!$H:$H,'1. INGRESOS'!$B:$B,H$2,'1. INGRESOS'!$K:$K,$B8) | I8: =SUMIFS('1. INGRESOS'!$H:$H,'1. INGRESOS'!$B:$B,I$2,'1. INGRESOS'!$K:$K,$B8) | J8: =SUMIFS('1. INGRESOS'!$H:$H,'1. INGRESOS'!$B:$B,J$2,'1. INGRESOS'!$K:$K,$B8) | K8: =SUMIFS('1. INGRESOS'!$H:$H,'1. INGRESOS'!$B:$B,K$2,'1. INGRESOS'!$K:$K,$B8) | L8: =SUMIFS('1. INGRESOS'!$H:$H,'1. INGRESOS'!$B:$B,L$2,'1. INGRESOS'!$K:$K,$B8) | ... AB8: =SUMIFS('1. INGRESOS'!$H:$H,'1. INGRESOS'!$B:$B,AB$2,'1. INGRESOS'!$K:$K,$B8) | AC8: =IFERROR(AVERAGE(E8:U8),"")
A9: Ferias | B9: =CANALES!$A$6 | C9: $ | E9: =SUMIFS('1. INGRESOS'!$H:$H,'1. INGRESOS'!$B:$B,E$2,'1. INGRESOS'!$K:$K,$B9) | F9: =SUMIFS('1. INGRESOS'!$H:$H,'1. INGRESOS'!$B:$B,F$2,'1. INGRESOS'!$K:$K,$B9) | G9: =SUMIFS('1. INGRESOS'!$H:$H,'1. INGRESOS'!$B:$B,G$2,'1. INGRESOS'!$K:$K,$B9) | H9: =SUMIFS('1. INGRESOS'!$H:$H,'1. INGRESOS'!$B:$B,H$2,'1. INGRESOS'!$K:$K,$B9) | I9: =SUMIFS('1. INGRESOS'!$H:$H,'1. INGRESOS'!$B:$B,I$2,'1. INGRESOS'!$K:$K,$B9) | J9: =SUMIFS('1. INGRESOS'!$H:$H,'1. INGRESOS'!$B:$B,J$2,'1. INGRESOS'!$K:$K,$B9) | K9: =SUMIFS('1. INGRESOS'!$H:$H,'1. INGRESOS'!$B:$B,K$2,'1. INGRESOS'!$K:$K,$B9) | L9: =SUMIFS('1. INGRESOS'!$H:$H,'1. INGRESOS'!$B:$B,L$2,'1. INGRESOS'!$K:$K,$B9) | ... AB9: =SUMIFS('1. INGRESOS'!$H:$H,'1. INGRESOS'!$B:$B,AB$2,'1. INGRESOS'!$K:$K,$B9) | AC9: =IFERROR(AVERAGE(E9:U9),"")
A10: MIX CANAL %
A11: % HoReCa | C11: % | E11: =IF(E$5=0,"",E$6/E$5) | F11: =IF(F$5=0,"",F$6/F$5) | G11: =IF(G$5=0,"",G$6/G$5) | H11: =IF(H$5=0,"",H$6/H$5) | I11: =IF(I$5=0,"",I$6/I$5) | J11: =IF(J$5=0,"",J$6/J$5) | K11: =IF(K$5=0,"",K$6/K$5) | L11: =IF(L$5=0,"",L$6/L$5) | ... AB11: =IF(AB$5=0,"",AB$6/AB$5) | AC11: =IFERROR(AVERAGE(E11:U11),"")
A12: % B2C | C12: % | E12: =IF(E$5=0,"",E$7/E$5) | F12: =IF(F$5=0,"",F$7/F$5) | G12: =IF(G$5=0,"",G$7/G$5) | H12: =IF(H$5=0,"",H$7/H$5) | I12: =IF(I$5=0,"",I$7/I$5) | J12: =IF(J$5=0,"",J$7/J$5) | K12: =IF(K$5=0,"",K$7/K$5) | L12: =IF(L$5=0,"",L$7/L$5) | ... AB12: =IF(AB$5=0,"",AB$7/AB$5) | AC12: =IFERROR(AVERAGE(E12:U12),"")
A13: % Delivery | C13: % | E13: =IF(E$5=0,"",E$8/E$5) | F13: =IF(F$5=0,"",F$8/F$5) | G13: =IF(G$5=0,"",G$8/G$5) | H13: =IF(H$5=0,"",H$8/H$5) | I13: =IF(I$5=0,"",I$8/I$5) | J13: =IF(J$5=0,"",J$8/J$5) | K13: =IF(K$5=0,"",K$8/K$5) | L13: =IF(L$5=0,"",L$8/L$5) | ... AB13: =IF(AB$5=0,"",AB$8/AB$5) | AC13: =IFERROR(AVERAGE(E13:U13),"")
A14: % Ferias | C14: % | E14: =IF(E$5=0,"",E$9/E$5) | F14: =IF(F$5=0,"",F$9/F$5) | G14: =IF(G$5=0,"",G$9/G$5) | H14: =IF(H$5=0,"",H$9/H$5) | I14: =IF(I$5=0,"",I$9/I$5) | J14: =IF(J$5=0,"",J$9/J$5) | K14: =IF(K$5=0,"",K$9/K$5) | L14: =IF(L$5=0,"",L$9/L$5) | ... AB14: =IF(AB$5=0,"",AB$9/AB$5) | AC14: =IFERROR(AVERAGE(E14:U14),"")
A15: VOLUMEN Y TICKETS
A16: N Transacciones Total | C16: # | E16: =COUNTIFS('1. INGRESOS'!$B:$B,E$2) | F16: =COUNTIFS('1. INGRESOS'!$B:$B,F$2) | G16: =COUNTIFS('1. INGRESOS'!$B:$B,G$2) | H16: =COUNTIFS('1. INGRESOS'!$B:$B,H$2) | I16: =COUNTIFS('1. INGRESOS'!$B:$B,I$2) | J16: =COUNTIFS('1. INGRESOS'!$B:$B,J$2) | K16: =COUNTIFS('1. INGRESOS'!$B:$B,K$2) | L16: =COUNTIFS('1. INGRESOS'!$B:$B,L$2) | ... AB16: =COUNTIFS('1. INGRESOS'!$B:$B,AB$2) | AC16: =IFERROR(AVERAGE(E16:U16),"")
A17: N Trans HoReCa | B17: =CANALES!$A$3 | C17: # | E17: =COUNTIFS('1. INGRESOS'!$B:$B,E$2,'1. INGRESOS'!$K:$K,$B17) | F17: =COUNTIFS('1. INGRESOS'!$B:$B,F$2,'1. INGRESOS'!$K:$K,$B17) | G17: =COUNTIFS('1. INGRESOS'!$B:$B,G$2,'1. INGRESOS'!$K:$K,$B17) | H17: =COUNTIFS('1. INGRESOS'!$B:$B,H$2,'1. INGRESOS'!$K:$K,$B17) | I17: =COUNTIFS('1. INGRESOS'!$B:$B,I$2,'1. INGRESOS'!$K:$K,$B17) | J17: =COUNTIFS('1. INGRESOS'!$B:$B,J$2,'1. INGRESOS'!$K:$K,$B17) | K17: =COUNTIFS('1. INGRESOS'!$B:$B,K$2,'1. INGRESOS'!$K:$K,$B17) | L17: =COUNTIFS('1. INGRESOS'!$B:$B,L$2,'1. INGRESOS'!$K:$K,$B17) | ... AB17: =COUNTIFS('1. INGRESOS'!$B:$B,AB$2,'1. INGRESOS'!$K:$K,$B17) | AC17: =IFERROR(AVERAGE(E17:U17),"")
A18: N Trans B2C | B18: =CANALES!$A$4 | C18: # | E18: =COUNTIFS('1. INGRESOS'!$B:$B,E$2,'1. INGRESOS'!$K:$K,$B18) | F18: =COUNTIFS('1. INGRESOS'!$B:$B,F$2,'1. INGRESOS'!$K:$K,$B18) | G18: =COUNTIFS('1. INGRESOS'!$B:$B,G$2,'1. INGRESOS'!$K:$K,$B18) | H18: =COUNTIFS('1. INGRESOS'!$B:$B,H$2,'1. INGRESOS'!$K:$K,$B18) | I18: =COUNTIFS('1. INGRESOS'!$B:$B,I$2,'1. INGRESOS'!$K:$K,$B18) | J18: =COUNTIFS('1. INGRESOS'!$B:$B,J$2,'1. INGRESOS'!$K:$K,$B18) | K18: =COUNTIFS('1. INGRESOS'!$B:$B,K$2,'1. INGRESOS'!$K:$K,$B18) | L18: =COUNTIFS('1. INGRESOS'!$B:$B,L$2,'1. INGRESOS'!$K:$K,$B18) | ... AB18: =COUNTIFS('1. INGRESOS'!$B:$B,AB$2,'1. INGRESOS'!$K:$K,$B18) | AC18: =IFERROR(AVERAGE(E18:U18),"")
A19: N Trans Delivery | B19: =CANALES!$A$5 | C19: # | E19: =COUNTIFS('1. INGRESOS'!$B:$B,E$2,'1. INGRESOS'!$K:$K,$B19) | F19: =COUNTIFS('1. INGRESOS'!$B:$B,F$2,'1. INGRESOS'!$K:$K,$B19) | G19: =COUNTIFS('1. INGRESOS'!$B:$B,G$2,'1. INGRESOS'!$K:$K,$B19) | H19: =COUNTIFS('1. INGRESOS'!$B:$B,H$2,'1. INGRESOS'!$K:$K,$B19) | I19: =COUNTIFS('1. INGRESOS'!$B:$B,I$2,'1. INGRESOS'!$K:$K,$B19) | J19: =COUNTIFS('1. INGRESOS'!$B:$B,J$2,'1. INGRESOS'!$K:$K,$B19) | K19: =COUNTIFS('1. INGRESOS'!$B:$B,K$2,'1. INGRESOS'!$K:$K,$B19) | L19: =COUNTIFS('1. INGRESOS'!$B:$B,L$2,'1. INGRESOS'!$K:$K,$B19) | ... AB19: =COUNTIFS('1. INGRESOS'!$B:$B,AB$2,'1. INGRESOS'!$K:$K,$B19) | AC19: =IFERROR(AVERAGE(E19:U19),"")
A20: Ticket Prom HoReCa | C20: $ | E20: =IF(E$17=0,"",E$6/E$17) | F20: =IF(F$17=0,"",F$6/F$17) | G20: =IF(G$17=0,"",G$6/G$17) | H20: =IF(H$17=0,"",H$6/H$17) | I20: =IF(I$17=0,"",I$6/I$17) | J20: =IF(J$17=0,"",J$6/J$17) | K20: =IF(K$17=0,"",K$6/K$17) | L20: =IF(L$17=0,"",L$6/L$17) | ... AB20: =IF(AB$17=0,"",AB$6/AB$17) | AC20: =IFERROR(AVERAGE(E20:U20),"")
A21: Ticket Prom B2C | C21: $ | E21: =IF(E$18=0,"",E$7/E$18) | F21: =IF(F$18=0,"",F$7/F$18) | G21: =IF(G$18=0,"",G$7/G$18) | H21: =IF(H$18=0,"",H$7/H$18) | I21: =IF(I$18=0,"",I$7/I$18) | J21: =IF(J$18=0,"",J$7/J$18) | K21: =IF(K$18=0,"",K$7/K$18) | L21: =IF(L$18=0,"",L$7/L$18) | ... AB21: =IF(AB$18=0,"",AB$7/AB$18) | AC21: =IFERROR(AVERAGE(E21:U21),"")
A22: Ticket Prom Delivery | C22: $ | E22: =IF(E$19=0,"",E$8/E$19) | F22: =IF(F$19=0,"",F$8/F$19) | G22: =IF(G$19=0,"",G$8/G$19) | H22: =IF(H$19=0,"",H$8/H$19) | I22: =IF(I$19=0,"",I$8/I$19) | J22: =IF(J$19=0,"",J$8/J$19) | K22: =IF(K$19=0,"",K$8/K$19) | L22: =IF(L$19=0,"",L$8/L$19) | ... AB22: =IF(AB$19=0,"",AB$8/AB$19) | AC22: =IFERROR(AVERAGE(E22:U22),"")
A23: Unidades Vendidas (items) | C23: # | E23: 2920 | F23: 3024 | G23: 5926 | H23: 4855 | I23: 3524 | J23: 1189 | K23: 2003 | L23: 995 | M23: 1294 | N23: 1863 | O23: 4321 | P23: 3353 | Q23: 1429 | R23: 1317 | S23: 1931 | T23: 2041 | U23: 1143 | AC23: 2537
A25: EGRESOS POR CENTRO DE COSTO
A26: Total Egresos | C26: $ | E26: =SUMIFS('2. EGRESOS'!$H:$H,'2. EGRESOS'!$B:$B,E$2) | F26: =SUMIFS('2. EGRESOS'!$H:$H,'2. EGRESOS'!$B:$B,F$2) | G26: =SUMIFS('2. EGRESOS'!$H:$H,'2. EGRESOS'!$B:$B,G$2) | H26: =SUMIFS('2. EGRESOS'!$H:$H,'2. EGRESOS'!$B:$B,H$2) | I26: =SUMIFS('2. EGRESOS'!$H:$H,'2. EGRESOS'!$B:$B,I$2) | J26: =SUMIFS('2. EGRESOS'!$H:$H,'2. EGRESOS'!$B:$B,J$2) | K26: =SUMIFS('2. EGRESOS'!$H:$H,'2. EGRESOS'!$B:$B,K$2) | L26: =SUMIFS('2. EGRESOS'!$H:$H,'2. EGRESOS'!$B:$B,L$2) | ... AB26: =SUMIFS('2. EGRESOS'!$H:$H,'2. EGRESOS'!$B:$B,AB$2) | AC26: =IFERROR(AVERAGE(E26:U26),"")
A27: CC1 Costos Producto | B27: =CCs!$A$2 | C27: $ | E27: =SUMIFS('2. EGRESOS'!$H:$H,'2. EGRESOS'!$B:$B,E$2,'2. EGRESOS'!$O:$O,$B27) | F27: =SUMIFS('2. EGRESOS'!$H:$H,'2. EGRESOS'!$B:$B,F$2,'2. EGRESOS'!$O:$O,$B27) | G27: =SUMIFS('2. EGRESOS'!$H:$H,'2. EGRESOS'!$B:$B,G$2,'2. EGRESOS'!$O:$O,$B27) | H27: =SUMIFS('2. EGRESOS'!$H:$H,'2. EGRESOS'!$B:$B,H$2,'2. EGRESOS'!$O:$O,$B27) | I27: =SUMIFS('2. EGRESOS'!$H:$H,'2. EGRESOS'!$B:$B,I$2,'2. EGRESOS'!$O:$O,$B27) | J27: =SUMIFS('2. EGRESOS'!$H:$H,'2. EGRESOS'!$B:$B,J$2,'2. EGRESOS'!$O:$O,$B27) | K27: =SUMIFS('2. EGRESOS'!$H:$H,'2. EGRESOS'!$B:$B,K$2,'2. EGRESOS'!$O:$O,$B27) | L27: =SUMIFS('2. EGRESOS'!$H:$H,'2. EGRESOS'!$B:$B,L$2,'2. EGRESOS'!$O:$O,$B27) | ... AB27: =SUMIFS('2. EGRESOS'!$H:$H,'2. EGRESOS'!$B:$B,AB$2,'2. EGRESOS'!$O:$O,$B27) | AC27: =IFERROR(AVERAGE(E27:U27),"")
A28: CC2 Sueldos y RRHH | B28: =CCs!$A$3 | C28: $ | E28: =SUMIFS('2. EGRESOS'!$H:$H,'2. EGRESOS'!$B:$B,E$2,'2. EGRESOS'!$O:$O,$B28) | F28: =SUMIFS('2. EGRESOS'!$H:$H,'2. EGRESOS'!$B:$B,F$2,'2. EGRESOS'!$O:$O,$B28) | G28: =SUMIFS('2. EGRESOS'!$H:$H,'2. EGRESOS'!$B:$B,G$2,'2. EGRESOS'!$O:$O,$B28) | H28: =SUMIFS('2. EGRESOS'!$H:$H,'2. EGRESOS'!$B:$B,H$2,'2. EGRESOS'!$O:$O,$B28) | I28: =SUMIFS('2. EGRESOS'!$H:$H,'2. EGRESOS'!$B:$B,I$2,'2. EGRESOS'!$O:$O,$B28) | J28: =SUMIFS('2. EGRESOS'!$H:$H,'2. EGRESOS'!$B:$B,J$2,'2. EGRESOS'!$O:$O,$B28) | K28: =SUMIFS('2. EGRESOS'!$H:$H,'2. EGRESOS'!$B:$B,K$2,'2. EGRESOS'!$O:$O,$B28) | L28: =SUMIFS('2. EGRESOS'!$H:$H,'2. EGRESOS'!$B:$B,L$2,'2. EGRESOS'!$O:$O,$B28) | ... AB28: =SUMIFS('2. EGRESOS'!$H:$H,'2. EGRESOS'!$B:$B,AB$2,'2. EGRESOS'!$O:$O,$B28) | AC28: =IFERROR(AVERAGE(E28:U28),"")
A29: CC3 Infraestructura | B29: =CCs!$A$4 | C29: $ | E29: =SUMIFS('2. EGRESOS'!$H:$H,'2. EGRESOS'!$B:$B,E$2,'2. EGRESOS'!$O:$O,$B29) | F29: =SUMIFS('2. EGRESOS'!$H:$H,'2. EGRESOS'!$B:$B,F$2,'2. EGRESOS'!$O:$O,$B29) | G29: =SUMIFS('2. EGRESOS'!$H:$H,'2. EGRESOS'!$B:$B,G$2,'2. EGRESOS'!$O:$O,$B29) | H29: =SUMIFS('2. EGRESOS'!$H:$H,'2. EGRESOS'!$B:$B,H$2,'2. EGRESOS'!$O:$O,$B29) | I29: =SUMIFS('2. EGRESOS'!$H:$H,'2. EGRESOS'!$B:$B,I$2,'2. EGRESOS'!$O:$O,$B29) | J29: =SUMIFS('2. EGRESOS'!$H:$H,'2. EGRESOS'!$B:$B,J$2,'2. EGRESOS'!$O:$O,$B29) | K29: =SUMIFS('2. EGRESOS'!$H:$H,'2. EGRESOS'!$B:$B,K$2,'2. EGRESOS'!$O:$O,$B29) | L29: =SUMIFS('2. EGRESOS'!$H:$H,'2. EGRESOS'!$B:$B,L$2,'2. EGRESOS'!$O:$O,$B29) | ... AB29: =SUMIFS('2. EGRESOS'!$H:$H,'2. EGRESOS'!$B:$B,AB$2,'2. EGRESOS'!$O:$O,$B29) | AC29: =IFERROR(AVERAGE(E29:U29),"")
A30: CC4 SaaS | B30: =CCs!$A$6 | C30: $ | E30: =SUMIFS('2. EGRESOS'!$H:$H,'2. EGRESOS'!$B:$B,E$2,'2. EGRESOS'!$O:$O,$B30) | F30: =SUMIFS('2. EGRESOS'!$H:$H,'2. EGRESOS'!$B:$B,F$2,'2. EGRESOS'!$O:$O,$B30) | G30: =SUMIFS('2. EGRESOS'!$H:$H,'2. EGRESOS'!$B:$B,G$2,'2. EGRESOS'!$O:$O,$B30) | H30: =SUMIFS('2. EGRESOS'!$H:$H,'2. EGRESOS'!$B:$B,H$2,'2. EGRESOS'!$O:$O,$B30) | I30: =SUMIFS('2. EGRESOS'!$H:$H,'2. EGRESOS'!$B:$B,I$2,'2. EGRESOS'!$O:$O,$B30) | J30: =SUMIFS('2. EGRESOS'!$H:$H,'2. EGRESOS'!$B:$B,J$2,'2. EGRESOS'!$O:$O,$B30) | K30: =SUMIFS('2. EGRESOS'!$H:$H,'2. EGRESOS'!$B:$B,K$2,'2. EGRESOS'!$O:$O,$B30) | L30: =SUMIFS('2. EGRESOS'!$H:$H,'2. EGRESOS'!$B:$B,L$2,'2. EGRESOS'!$O:$O,$B30) | ... AB30: =SUMIFS('2. EGRESOS'!$H:$H,'2. EGRESOS'!$B:$B,AB$2,'2. EGRESOS'!$O:$O,$B30) | AC30: =IFERROR(AVERAGE(E30:U30),"")
A31: CC5 Marketing | B31: =CCs!$A$7 | C31: $ | E31: =SUMIFS('2. EGRESOS'!$H:$H,'2. EGRESOS'!$B:$B,E$2,'2. EGRESOS'!$O:$O,$B31) | F31: =SUMIFS('2. EGRESOS'!$H:$H,'2. EGRESOS'!$B:$B,F$2,'2. EGRESOS'!$O:$O,$B31) | G31: =SUMIFS('2. EGRESOS'!$H:$H,'2. EGRESOS'!$B:$B,G$2,'2. EGRESOS'!$O:$O,$B31) | H31: =SUMIFS('2. EGRESOS'!$H:$H,'2. EGRESOS'!$B:$B,H$2,'2. EGRESOS'!$O:$O,$B31) | I31: =SUMIFS('2. EGRESOS'!$H:$H,'2. EGRESOS'!$B:$B,I$2,'2. EGRESOS'!$O:$O,$B31) | J31: =SUMIFS('2. EGRESOS'!$H:$H,'2. EGRESOS'!$B:$B,J$2,'2. EGRESOS'!$O:$O,$B31) | K31: =SUMIFS('2. EGRESOS'!$H:$H,'2. EGRESOS'!$B:$B,K$2,'2. EGRESOS'!$O:$O,$B31) | L31: =SUMIFS('2. EGRESOS'!$H:$H,'2. EGRESOS'!$B:$B,L$2,'2. EGRESOS'!$O:$O,$B31) | ... AB31: =SUMIFS('2. EGRESOS'!$H:$H,'2. EGRESOS'!$B:$B,AB$2,'2. EGRESOS'!$O:$O,$B31) | AC31: =IFERROR(AVERAGE(E31:U31),"")
